Workbook

Sheet Sheet1
D6: 一般見積価格
D8: 価格改定 | F8: 2025・3
F11: ﾈﾎﾟﾝ製品原価修正
G12: '08 04 25
G13: '08 05 30
G14: '08 12 02 | H14: BTU金額改定
G15: '09 04 01 | H15: 仕入製品価格改訂
G16: '10 12 17 | H16: 製品価格改訂
G17: '11 05 24 | H17: 管材・バルブ・樹脂管等の価格UP（20％）およびネポン原価改訂
G18: '14 08 18 | H18: 製品価格改訂
G19: '15 07 29 | H19: 製品価格改訂
G20: '19 05 08 | H20: 製品価格改訂
G21: '19 08 01 | H21: 製品価格・工事原価・管材及び部材価格改訂
G22: '20 04 16 | H22: 製品原価・部材価格改訂
G23: '21 05 31 | H23: 製品価格・管材及び部材価格改訂
G24: 22 03 28 | H24: 製品価格改訂
G25: 23 03 10 | H25: 製品・部材価格、人工単価改訂
... G27: 25 03 25 | H27: 製品・部材・管材価格改訂
F29: 塩ビ管原価修正
G30: '11 05 24
G31: '19 08 01
G32: '25 03 25
F34: ST熱交換器原価修正
G35: '07 07 17
F37: 標準項修正
G38: '19 11 06
G39: 22 07 14

Sheet 項目表
A1: 項目表 | E1: E3 | F1: E4
B2: 主項目 | E2: 工単価 | F2: 工原価 | G2: G3 | H2: G4 | J2: G6
A3: b3 | B3: ボイラ及びボイラ回り設備工事 | E3: 47500 | F3: 29400 | G3: 式 | H3: 機材運搬費 | J3: 井関農機株式会社
B4: ボイラ室内設備工事 | G4: ｾｯﾄ | H4: 試運転調整費 | J4: 渡辺パイプ株式会社
B5: ボイラ回り設備工事 | G5: 組 | H5: 現場諸経費 | J5: 東海物産株式会社
B6: 機械室内設備工事 | G6: ﾕﾆｯﾄ | H6: 機材小運搬費 | J6: イノチオアグリ株式会社
B7: 地中メイン配管設備工事 | G7: ﾀﾞｰｽ | H7: 現場立会い検査費 | J7: カネコ種苗株式会社
B8: メイン配管設備工事 | G8: 基 | H8: 消防関連打合せ費用 | J8: イワタニアグリグリーン株式会社
B9: 主要機器機材設備工事 | G9: 台 | H9: 大気汚染防止法関連打合せ費用 | J9: タキイ種苗株式会社
B10: CO2施用設備工事 | G10: 個 | H10: 消防立会い検査費 | J10: トヨタネ株式会社
B11: --------------- | G11: 本 | H11: タンク水張り検査費 | J11: 佐藤商事株式会社 神奈川支店
B12: 温室内暖房設備工事 | G12: 巻 | H12: 防油堤・基礎工事費 | J12: ﾔﾝﾏｰｸﾞﾘｰﾝｼｽﾃﾑ株式会社
B13: 温室内配管設備工事 | G13: 缶 | H13: 油水分離槽工事 | J13: サンキンB&G株式会社
B14: 温室内設備工事 | G14: m | H14: 道路横断補強工事 | J14: 株式会社誠和。
B15: 温室内温風暖房設備工事 | G15: ㎡ | H15: 塗装補修工事 | J15: ｼｰｱｲﾏﾃｯｸｽ株式会社
... B20: グリーンパッケージ設備工事 | G20: ﾄﾝ | H20: 消耗品雑材 | J20: 株式会社大仙関東支社
B21: 誰でもヒーポン設備工事 | J21: 株式会社大仙中部支社
B22: アグリネット設備工事 | J22: 株式会社大仙関西支社
B23: 土壌蒸気殺菌装置 | J23: 株式会社大仙四国支店
B24: 圃場蒸気殺菌装置 | J24: 株式会社大仙九州支社
B25: --------------- | F25: G25 | G25: ㎡ | J25: ---------------
B26: 地中放熱管設備工事 | G26: a | J26: 明友機工株式会社
B27: ベット配管設備工事 | G27: ha | J27: 富国工業株式会社
B28: 養液加温設備工事 | J28: 日之出産業株式会社
B29: 養液冷暖設備工事 | J29: 株式会社松本産業
B30: 温室空間冷房設備工事 | J30: 住栄農材株式会社
B31: --------------- | J31: 八江ｸﾞﾘｰﾝﾎﾟｰﾄ株式会社
B32: 天窓関連設備機器 | J32: 未来のｱｸﾞﾘ株式会社
B33: 温度制御設備機器 | J33: 株式会社タカミヤ
B34: 複合環境制御機器
B35: アグリネット設備機器
B36: ---------------
B37: オイルタンク及びオイル配管設備工事
B38: オイルタンク設備工事
B39: オイル配管設備工事
B40: 地下オイルタンク設備工事 | G40: G40 | H40: お打ち合わせ願います
B41: 消火器・標識設備工事 | H41: ご注文後1週間でお渡しできます
B42: 諸 経 費 | H42: ご注文後2週間でお渡しできます
B43: --------------- | H43: ご注文後3週間でお渡しできます
H44: ご注文後1ヶ月でお渡しできます
...

Sheet 機器表
K1: 品番 | L1: 品名 | M1: 型式 | O1: 小売価格 | P1: 原価 | Q1: 歩単 | S1: 品番 | T1: 品名 | U1: 型式 | W1: 小売価格 | X1: 原価 | Y1: 歩単 | AA1: 品番 | AB1: 品名 | AC1: 型式 | AE1: 小売価格 | AF1: 原価 | AG1: 歩単 | AI1: 品番 | AJ1: 品名 | AK1: 型式 | AM1: 小売価格 | AN1: 原価 | AO1: 歩単 | AQ1: 品番 | AR1: 品名 | AS1: 型式 | AU1: 小売価格 | AV1: 原価 | AW1: 歩単 | AY1: 品番 | AZ1: 品名 | BA1: 型式 | BC1: 小売価格 | BD1: 原価 | BE1: 歩単 | BG1: 品番 | BH1: 品名 | BI1: 型式 | BK1: 小売価格 | BL1: 原価 | BM1: 歩単 | BO1: 品番 | BP1: 品名 | BQ1: 型式 | BS1: 小売価格 | BT1: 原価 | BU1: 歩単 | BW1: 品番 | BX1: 品名 | BY1: 型式 | CA1: 小売価格 | CB1: 原価 | CC1: 歩単 | CE1: 品番 | CF1: 品名 | CG1: 型式 | CI1: 小売価格 | CJ1: 原価 | CK1: 歩単 | CM1: 品番 | CN1: 品名 | CO1: 型式 | CQ1: 小売価格 | CR1: 原価 | CS1: 歩単 | CU1: 品番 | CV1: 品名 | CW1: 型式 | CY1: 小売価格 | CZ1: 原価 | DA1: 歩単 | DC1: 品番 | DD1: 品名 | DE1: 型式 | DG1: 小売価格 | DH1: 原価 | DI1: 歩単 | DK1: 品番 | DL1: 品名 | DM1: 型式 | DO1: 小売価格 | DP1: 原価 | DQ1: 歩単 | DS1: 品番 | DT1: 品名 | DU1: 型式 | DW1: 小売価格 | DX1: 原価 | DY1: 歩単 | EA1: 品番 | EB1: 品名 | EC1: 型式 | EE1: 小売価格 | EF1: 原価 | EG1: 歩単 | EI1: 品番 | EJ1: 品名 | EK1: 型式 | EM1: 小売価格 | EN1: 原価 | EO1: 歩単 | EQ1: 品番 | ER1: 品名 | ES1: 型式 | EU1: 小売価格 | EV1: 原価 | EW1: 歩単 | EY1: 品番 | EZ1: 品名 | FA1: 型式 | FC1: 小売価格 | FD1: 原価 | FE1: 歩単 | FG1: 品番 | FH1: 品名 | FI1: 型式 | FK1: 小売価格 | FL1: 原価 | FM1: 歩単 | FO1: 品番 | FP1: 品名 | FQ1: 型式 | FS1: 小売価格 | FT1: 原価 | FU1: 歩単 | FW1: 品番 | FX1: 品名 | FY1: 型式 | GA1: 小売価格 | GB1: 原価 | GC1: 歩単 | GE1: 品番 | GF1: 品名 | GG1: 型式 | GI1: 小売価格 | GJ1: 原価 | GK1: 歩単 | GM1: 品番 | GN1: 品名 | GO1: 型式 | GQ1: 小売価格 | GR1: 原価 | GS1: 歩単 | GU1: 品番 | GV1: 品名 | GW1: 型式 | GY1: 小売価格 | GZ1: 原価 | HA1: 歩単
BL2: 0.43 | BP2: STKｴﾛﾌｨﾝﾁｭｰﾌﾞ | DP2: 0.15 | DU2: ホーコス株式会社 | DX2: 0.55 | EC2: ｵｲﾙﾀﾝｸ・消防関連 | EJ2: 煙道・煙突関連部材 | ER2: ﾎﾟﾘﾀﾞｸﾄ・ｸﾛｽﾗﾑﾀﾞｸﾄ | EZ2: ｽﾊﾟｲﾗﾙﾀﾞｸﾄ | FH2: ｱﾙﾐﾌﾚｷﾀﾞｸﾄ | FP2: ﾊｳｽｶｵﾝｷ(静音型) | GF2: ﾊｳｽｶｵﾝｷ(ｶﾞｽ焚き) | GN2: ﾋｰﾄｯﾌﾟ・ｶﾜｲﾀｰ | GV2: SGPｴﾛﾌｨﾝﾁｭｰﾌﾞ
B3: 1 | C3: ﾊｳｽｶｵﾝｷ 30型・29型 | D3: l3 | E3: 同上搬入据付工事 | I3: 機器減衰率係数 | K3: 049825000 | L3: ﾊｳｽｶｵﾝｷ | M3: HK2030TCV | N3: 台 | O3: 909000 | P3: 470450 | Q3: 1.25 | S3: 051111000 | T3: 小型温風機 | U3: KA-125 | V3: 台 | W3: 331000 | X3: 139730 | Y3: 0.52 | AA3: 038886000 | AB3: ｼｮｳｵﾝﾎﾞｲﾗ | AC3: SHB-310S1K | AD3: 台 | AE3: 512000 | AF3: 232620 | AG3: 1 | AI3: 052478000 | AJ3: ｼﾝｸﾛﾋｰﾀ | AK3: SBM100WNU_10 | AL3: 台 | AM3: 2579000 | AN3: 703660 | AO3: 2.3 | AQ3: 041992000 | AR3: ｵｰﾄｶﾝ | AS3: AWH-501A | AT3: 台 | AU3: 1000000 | AV3: 310890 | AW3: 1.3 | AY3: 026087000 | AZ3: ｸﾞﾘｰﾝｿｰﾗ | BA3: RHE-134E | BB3: 台 | BC3: 1845000 | BD3: 663790 | BE3: 1.2 | BG3: RB0000304 | BH3: 熱交換器 | BI3: ST-3(1m) | BJ3: 基 | BK3: 226000 | BL3: 81600 | BM3: 0.5 | BP3: ｴﾛﾌｨﾝﾁｭｰﾌﾞ（STK 5KF） | BQ3: 32A 25F 5500L | BR3: 本 | BS3: =ROUND(BT3/0.4,-3) -> 86000 | BT3: 34400 | BU3: 0.72 | BX3: ﾌｧﾝｺｲﾙﾕﾆｯﾄ | BY3: RF-20F | BZ3: 基 | CA3: 125000 | CB3: =CA3*0.48 -> 60000 | CC3: 1 | CF3: ｸｰﾘﾝｸﾞﾀﾜｰ | CG3: MT-514 | CH3: 基 | CI3: 120000 | CJ3: 66000 | CK3: 2.5 | CN3: 蓄熱ﾀﾝｸ | CO3: 100ﾘｯﾄﾙ | CP3: 基 | CQ3: 23000 | CR3: 15000 | CS3: 0.2 | CV3: ﾗｲﾝﾎﾟﾝﾌﾟ | CW3: 50Hz φ25 0.15kW | CX3: 台 | CY3: 102000 | CZ3: =ROUND(CY3*0.53,-1) -> 54060 | DA3: 0.3 | DC3: 052396000 | DD3: ｸﾞﾘｰﾝﾊﾟｯｹｰｼﾞ | DE3: NGP109TQX-J_4(親機) | DF3: ｾｯﾄ | DG3: 1573000 | DH3: 822710 | DI3: 2.9 | DL3: 空冷ﾁﾗｰﾕﾆｯﾄ | DM3: UWAP75A(3HP) | DN3: 基 | DO3: 1730000 | DP3: =ROUNDUP(DO3*$DP$2,-2) -> 259500 | DQ3: 0 | DT3: 膨張ﾀﾝｸ | DU3: ETU-100 ボールタップ一般型 | DV3: 台 | DW3: 352000 | DX3: 193600 | DY3: 0.3 | EA3: 047056000 | EB3: ｵｲﾙﾀﾝｸ | EC3: BOT-99 | ED3: 基 | EE3: 40100 | EF3: 17310 | EG3: 0.1 | EI3: 103230000 | EJ3: 煙突ｾｯﾄ | EK3: BEP-3P120A網付 | EL3: ｾｯﾄ | EM3: 33400 | EN3: 6360 | EO3: 0.7 | EQ3: 2500000022 | ER3: ﾎﾟﾘﾀﾞｸﾄ | ES3: 折幅400×200m(0.07) | ET3: 本 | EU3: 10690 | EV3: 4704 | EW3: 0 | EZ3: ｽﾊﾟｲﾗﾙﾀﾞｸﾄ(亜鉛) | FA3: φ200 | FB3: ｍ | FC3: 2100 | FD3: =FC3*0.65 -> 1365 | FE3: 0.16 | FG3: 186981000 | FH3: ｱﾙﾐﾌﾚｷﾀﾞｸﾄ | FI3: φ225×4000L | FJ3: 本 | FK3: 11600 | FL3: 2710 | FO3: 051234000 | FP3: ﾊｳｽｶｵﾝｷ | FQ3: HK2030GCSV | FR3: 台 | FS3: 1165000 | FT3: 498460 | FU3: 1.25 | FX3: ｴﾛﾌｨﾝ支持金具 | FY3: 1段1列 | FZ3: 本 | GA3: 18000 | GB3: 9000 | GC3: 0.11 | GE3: 051051000 | GF3: ﾊｳｽｶｵﾝｷ（LPｶﾞｽ焚き） | GG3: HK2030TCL | GH3: 台 | GI3: 1161000 | GJ3: 549400 | GK3: 1.25 | GM3: 043222000 | GN3: ﾋｰﾄｯﾌﾟ | GO3: HT-201E | GP3: 台 | GQ3: 693000 | GR3: 234170 | GS3: 0.7 | GV3: SGPｴﾛﾌｨﾝﾁｭｰﾌﾞ | GW3: 32A 25F 5500L | GX3: 本 | GY3: =ROUND(GZ3/0.33,-3) -> 111000 | GZ3: 36600 | HA3: 0.72
B4: 3 | C4: ﾊｳｽｶｵﾝｷ 静音型 | D4: fp3 | E4: 同上架台工事 | I4: 2 | K4: 049826000 | L4: ﾊｳｽｶｵﾝｷ | M4: HK2030TEV | N4: 台 | O4: 925000 | P4: 481600 | Q4: 1.25 | S4: 051113000 | T4: 小型温風機 | U4: KA-205 | V4: 台 | W4: 400000 | X4: 143600 | Y4: 0.7 | AA4: 038884000 | AB4: ｼｮｳｵﾝﾎﾞｲﾗ | AC4: SHB-310TK | AD4: 台 | AE4: 515000 | AF4: 232880 | AG4: 1 | AI4: 052479000 | AJ4: ｼﾝｸﾛﾋｰﾀ | AK4: SBM100WMU_10 | AL4: 台 | AM4: 2579000 | AN4: 702500 | AO4: 2.3 | AQ4: 041993000 | AR4: ｵｰﾄｶﾝ | AS4: AWH-601A | AT4: 台 | AU4: 1039000 | AV4: 313300 | AW4: 1.4 | AY4: 026090000 | AZ4: ｸﾞﾘｰﾝｿｰﾗ | BA4: RHE-154C | BB4: 台 | BC4: 1915000 | BD4: 710880 | BE4: 1.4 | BG4: RB0000305 | BH4: 熱交換器 | BI4: ST-5(1m) | BJ4: 基 | BK4: 291000 | BL4: 105600 | BM4: 0.6 | BP4: ｴﾛﾌｨﾝﾁｭｰﾌﾞ（STK 5KF） | BQ4: 32A 25F 4000L | BR4: 本 | BS4: =ROUND(BT4/0.4,-3) -> 79000 | BT4: 31600 | BU4: 0.52 | BX4: ﾌｧﾝｺｲﾙﾕﾆｯﾄ | BY4: RF-30F | BZ4: 基 | CA4: 141000 | CB4: =CA4*0.48 -> 67680 | CC4: 1.25 | CF4: ｸｰﾘﾝｸﾞﾀﾜｰ | CG4: MT-814 | CH4: 基 | CI4: 150000 | CJ4: 82000 | CK4: 2.5 | CN4: 蓄熱ﾀﾝｸ | CO4: 200ﾘｯﾄﾙ | CP4: 基 | CQ4: 31000 | CR4: 20000 | CS4: 0.2 | CV4: ---------- | DC4: 052395000 | DD4: ｸﾞﾘｰﾝﾊﾟｯｹｰｼﾞ | DE4: NGP109TQ-J_4(子機) | DF4: ｾｯﾄ | DG4: 1357000 | DH4: 746140 | DI4: 2.9 | DL4: 空冷ﾁﾗｰﾕﾆｯﾄ | DM4: UWAA125A(5HP) | DN4: 基 | DO4: 3080000 | DP4: =ROUNDUP(DO4*0.3,-2) -> 924000 | DQ4: 0 | DT4: 膨張ﾀﾝｸ | DU4: ETU-200 ボールタップ一般型 | DV4: 台 | DW4: 438000 | DX4: 240900 | DY4: 0.3 | EA4: 047057000 | EB4: ｵｲﾙﾀﾝｸ | EC4: BOT-200 | ED4: 基 | EE4: 84000 | EF4: 26080 | EG4: 0.2 | EI4: 104720000 | EJ4: 煙突ｾｯﾄ | EK4: BEP-3P1504網付 | EL4: ｾｯﾄ | EM4: 51300 | EN4: 13770 | EO4: 0.7 | EQ4: 2500000101 | ER4: ﾎﾟﾘﾀﾞｸﾄ | ES4: 折幅475×100m | ET4: 本 | EU4: 9070 | EV4: 3990 | EW4: 0 | EZ4: ｽﾊﾟｲﾗﾙﾀﾞｸﾄ(亜鉛) | FA4: φ225 | FB4: ｍ | FC4: 2500 | FD4: =FC4*0.65 -> 1625 | FE4: 0.18 | FH4: --------------- | FO4: 051235000 | FP4: ﾊｳｽｶｵﾝｷ | FQ4: HK2030GESV | FR4: 台 | FS4: 1183000 | FU4: 1.25 | FX4: ｴﾛﾌｨﾝ支持金具 | FY4: 2段1列 | FZ4: 本 | GA4: 22000 | GB4: 11000 | GC4: 0.15 | GE4: 051061000 | GF4: ﾊｳｽｶｵﾝｷ（LPｶﾞｽ焚き） | GG4: HK2030TEL | GH4: 台 | GI4: 1186000 | GJ4: 558480 | GK4: 1.25 | GM4: 043223000 | GN4: ﾋｰﾄｯﾌﾟ | GO4: HT-321F | GP4: 台 | GQ4: 788000 | GR4: 222040 | GS4: 0.9 | GV4: SGPｴﾛﾌｨﾝﾁｭｰﾌﾞ | GW4: 32A 25F 4000L | GX4: 本 | GY4: =ROUND(GZ4/0.33,-3) -> 100000 | GZ4: 33100 | HA4: 0.52
B5: 4 | C5: ﾊｳｽｶｵﾝｷ ｶﾞｽ焚き | D5: gf3 | E5: 同上架台及び機器据付工事 | I5: 0.15 | K5: 051779000 | L5: ﾊｳｽｶｵﾝｷ | M5: HK2030TRV | N5: 台 | O5: 1166000 | P5: 595420 | Q5: 1.25 | S5: 051115000 | T5: 小型温風機 | U5: KA-325 | V5: 台 | W5: 492000 | X5: 165270 | Y5: 0.9 | AA5: 038885000 | AB5: ｼｮｳｵﾝﾎﾞｲﾗ | AC5: SHB-310TK4 | AD5: 台 | AE5: 573000 | AF5: 235070 | AG5: 1 | AI5: 052480000 | AJ5: ｼﾝｸﾛﾋｰﾀ | AK5: SBM100WLU_10 | AL5: 台 | AM5: 2579000 | AN5: 702760 | AO5: 2.3 | AQ5: 041994000 | AR5: ｵｰﾄｶﾝ | AS5: AWH-701A | AT5: 台 | AU5: 1116000 | AV5: 313300 | AW5: 1.55 | AZ5: ---------- | BG5: RB0000306 | BH5: 熱交換器 | BI5: ST-8(1m) | BJ5: 基 | BK5: 385000 | BL5: 139200 | BM5: 0.7 | BP5: ｴﾛﾌｨﾝﾁｭｰﾌﾞ（STK 5KF） | BQ5: 32A 25F 3500L | BR5: 本 | BS5: =ROUND(BT5/0.4,-3) -> 76000 | BT5: 30400 | BU5: 0.46 | BX5: ﾌｧﾝｺｲﾙﾕﾆｯﾄ | BY5: RF-40F | BZ5: 基 | CA5: 149000 | CB5: =CA5*0.48 -> 71520 | CC5: 1.25 | CF5: ｸｰﾘﾝｸﾞﾀﾜｰ | CG5: MT-1014 | CH5: 基 | CI5: 175000 | CJ5: 96000 | CK5: 2.75 | CN5: 蓄熱ﾀﾝｸ | CO5: 500ﾘｯﾄﾙ | CP5: 基 | CQ5: 46000 | CR5: 30000 | CS5: 0.3 | CV5: ﾗｲﾝﾎﾟﾝﾌﾟ | CW5: 50Hz φ32 0.25kW | CX5: 台 | CY5: 139000 | CZ5: =ROUND(CY5*0.53,-1) -> 73670 | DA5: 0.3 | DD5: 室外機平置台(H500) | DF5: 式 | DG5: 150000 | DH5: 43450 | DL5: 空冷ﾁﾗｰﾕﾆｯﾄ | DM5: UWAA190A(8HP) | DN5: 基 | DO5: 3950000 | DP5: =ROUNDUP(DO5*0.3,-2) -> 1185000 | DQ5: 0 | DT5: 膨張ﾀﾝｸ | DU5: ETU-300 ボールタップ一般型 | DV5: 台 | DW5: 548000 | DX5: 301400 | DY5: 0.5 | EA5: 150729000 | EB5: ｵｲﾙﾀﾝｸ | EC5: BOT-490 | ED5: 基 | EE5: 119900 | EF5: 52990 | EG5: 0.3 | EI5: 102387000 | EJ5: 煙突ｾｯﾄ | EK5: BEP-3P2252網付 | EL5: ｾｯﾄ | EM5: 72800 | EN5: 23470 | EO5: 0.7 | EQ5: 2500000025 | ER5: ﾎﾟﾘﾀﾞｸﾄ | ES5: 折幅475×200m(0.07) | ET5: 本 | EU5: 12700 | EV5: 5586 | EW5: 0 | EZ5: ｽﾊﾟｲﾗﾙﾀﾞｸﾄ(亜鉛) | FA5: φ250 | FB5: ｍ | FC5: 2600 | FD5: =FC5*0.65 -> 1690 | FE5: 0.18 | FH5: 亜鉛鋼板ﾆｯﾌﾟﾙ | FI5: φ225 | FJ5: 本 | FK5: 710 | FL5: 426 | FP5: ---------- | FX5: ｴﾛﾌｨﾝ支持金具 | FY5: 1段2列 | FZ5: 本 | GA5: 20000 | GB5: 10000 | GC5: 0.12 | GE5: 051053000 | GF5: ﾊｳｽｶｵﾝｷ（LPｶﾞｽ焚き） | GG5: HK3030TCL | GH5: 台 | GI5: 1392000 | GJ5: 615910 | GK5: 1.45 | GM5: 043224000 | GN5: ﾋｰﾄｯﾌﾟ | GO5: HT-322E | GP5: 台 | GQ5: 886000 | GR5: 252490 | GS5: 0.7 | GV5: SGPｴﾛﾌｨﾝﾁｭｰﾌﾞ | GW5: 32A 25F 3500L | GX5: 本 | GY5: =ROUND(GZ5/0.33,-3) -> 97000 | GZ5: 31900 | HA5: 0.46
B6: 5 | C6: 小型温風機・ｸﾞﾛｳｴｱ | D6: t3 | E6: 同上架台及び据付工事 | K6: 049827000 | L6: ﾊｳｽｶｵﾝｷ | M6: HK3030TCV | N6: 台 | O6: 1129000 | P6: 490810 | Q6: 1.45 | S6: 051117000 | T6: 小型温風機 | U6: KA-325T | V6: 台 | W6: 542000 | X6: 176620 | Y6: 0.9 | AB6: ----------- | AI6: 052481000 | AJ6: ｼﾝｸﾛﾋｰﾀ | AK6: SBM100WNUJ_2（水道直結仕様） | AL6: 台 | AM6: 2730000 | AN6: 728300 | AO6: 2.3 | AQ6: 041995000 | AR6: ｵｰﾄｶﾝ | AS6: AWH-801A | AT6: 台 | AU6: 1185000 | AV6: 379920 | AW6: 1.65 | AY6: 105332000 | AZ6: ﾀﾞｲﾚｸﾄﾌｧﾝ | BA6: DFN-102TE | BB6: 台 | BC6: 207000 | BD6: 77000 | BE6: 0.2 | BG6: RB0000307 | BH6: 熱交換器 | BI6: ST-10(1m) | BJ6: 基 | BK6: 543000 | BL6: 196800 | BM6: 0.8 | BP6: ｴﾛﾌｨﾝﾁｭｰﾌﾞ（STK 5KF） | BQ6: 32A 25F 3000L | BR6: 本 | BS6: =ROUND(BT6/0.4,-3) -> 74000 | BT6: 29400 | BU6: 0.4 | BX6: ﾌｧﾝｺｲﾙﾕﾆｯﾄ | BY6: RF-60F | BZ6: 基 | CA6: 173000 | CB6: =CA6*0.48 -> 83040 | CC6: 1.5 | CF6: ｸｰﾘﾝｸﾞﾀﾜｰ | CG6: MT-1514 | CH6: 基 | CI6: 226000 | CJ6: 124000 | CK6: 2.75 | CN6: 蓄熱ﾀﾝｸ | CO6: 750ﾘｯﾄﾙ | CP6: 基 | CQ6: 118000 | CR6: 77000 | CS6: 0.3 | CV6: ﾗｲﾝﾎﾟﾝﾌﾟ | CW6: 50Hz φ32 0.4kW | CX6: 台 | CY6: 169000 | CZ6: =ROUND(CY6*0.53,-1) -> 89570 | DA6: 0.5 | DC6: 044798000 | DD6: ﾌﾚｯｸｽﾌﾛｰｱﾀﾞﾌﾟﾀｰｾｯﾄ | DF6: 式 | DG6: 170800 | DH6: 48200 | DL6: 空冷ﾁﾗｰﾕﾆｯﾄ | DM6: UWAA250A(10HP) | DN6: 基 | DO6: 4730000 | DP6: =ROUNDUP(DO6*0.3,-2) -> 1419000 | DQ6: 0 | DT6: 膨張ﾀﾝｸ | DU6: ETU-500 ボールタップ一般型 | DV6: 台 | DW6: 733000 | DX6: 403200 | DY6: 0.5 | EB6: ｵｲﾙﾀﾝｸ | EC6: BOT-900 | ED6: 基 | EE6: 330000 | EF6: 139200 | EG6: 1 | EI6: 002290000 | EJ6: 煙突ｾｯﾄ | EK6: BEP-HB1201 | EL6: ｾｯﾄ | EM6: 65700 | EN6: 23160 | EO6: 0.5 | EQ6: 2500000102 | ER6: ﾎﾟﾘﾀﾞｸﾄ | ES6: 折幅630×50m | ET6: 本 | EU6: 6020 | EV6: 2646 | EW6: 0 | EZ6: ｽﾊﾟｲﾗﾙﾀﾞｸﾄ(亜鉛) | FA6: φ300 | FB6: ｍ | FC6: 3200 | FD6: =FC6*0.65 -> 2080 | FE6: 0.18 | FH6: 亜鉛鋼板T管 | FI6: φ225 | FJ6: 本 | FK6: 4250 | FL6: 2550 | FO6: 051236000 | FP6: ﾊｳｽｶｵﾝｷ | FQ6: HK3030GCSV | FR6: 台 | FS6: 1407000 | FT6: 515700 | FU6: 1.45 | FX6: ｴﾛﾌｨﾝ支持金具 | FY6: 2段2列 | FZ6: 本 | GA6: 24800 | GB6: 12400 | GC6: 0.2 | GE6: 051063000 | GF6: ﾊｳｽｶｵﾝｷ（LPｶﾞｽ焚き） | GG6: HK3030TEL | GH6: 台 | GI6: 1407000 | GJ6: 632630 | GK6: 1.45 | GM6: 043225000 | GN6: ﾋｰﾄｯﾌﾟ | GO6: HT-322F | GP6: 台 | GQ6: 886000 | GR6: 249260 | GS6: 0.9 | GV6: SGPｴﾛﾌｨﾝﾁｭｰﾌﾞ | GW6: 32A 25F 3000L | GX6: 本 | GY6: =ROUND(GZ6/0.33,-3) -> 93000 | GZ6: 30700 | HA6: 0.4
B7: 6 | C7: ﾊｳｽﾎﾞｲﾗ | D7: ab3 | E7: 同上取付工事 | I7: ｴﾛﾌｨﾝ減衰率係数 | K7: 049828000 | L7: ﾊｳｽｶｵﾝｷ | M7: HK3030TEV | N7: 台 | O7: 1141000 | P7: 509220 | Q7: 1.45 | S7: 051119000 | T7: 小型温風機 | U7: KA-405T | V7: 台 | W7: 665000 | X7: 251450 | Y7: 1 | AA7: 025357000 | AB7: ﾊｳｽﾎﾞｲﾗ | AC7: HB-407TGA | AD7: 台 | AE7: 944000 | AF7: 458400 | AG7: 1.15 | AI7: 052482000 | AJ7: ｼﾝｸﾛﾋｰﾀ | AK7: SBM100WMUJ_2（水道直結仕様） | AL7: 台 | AM7: 2730000 | AN7: 728170 | AO7: 2.3 | AQ7: 041996000 | AR7: ｵｰﾄｶﾝ | AS7: AWH-901A | AT7: 台 | AU7: 1242000 | AV7: 382330 | AW7: 1.75 | AZ7: ---------- | BG7: RB0000308 | BH7: 熱交換器 | BI7: ST-20(1m) | BJ7: 基 | BK7: 676000 | BL7: 244800 | BM7: 1 | BP7: ｴﾛﾌｨﾝﾁｭｰﾌﾞ（STK 5KF） | BQ7: 32A 25F 2750L | BR7: 本 | BS7: =ROUND(BT7/0.4,-3) -> 73000 | BT7: 29000 | BU7: 0.36 | BX7: ﾌｧﾝｺｲﾙﾕﾆｯﾄ | BY7: RF-80F | BZ7: 基 | CA7: 210000 | CB7: =CA7*0.48 -> 100800 | CC7: 1.5 | CF7: ｸｰﾘﾝｸﾞﾀﾜｰ | CG7: MT-2014 | CH7: 基 | CI7: 277000 | CJ7: 152000 | CK7: 3 | CN7: 蓄熱ﾀﾝｸ | CO7: 1,000ﾘｯﾄﾙ | CP7: 基 | CQ7: 134000 | CR7: 88000 | CS7: 0.6 | CV7: ﾗｲﾝﾎﾟﾝﾌﾟ | CW7: 50Hz φ32 0.75kW | CX7: 台 | CY7: 225000 | CZ7: =ROUND(CY7*0.53,-1) -> 119250 | DA7: 0.5 | DC7: 028066000 | DD7: 省ｴﾈﾊｲﾌﾞﾘｯﾄﾞ制御盤 | DE7: NT-602 | DF7: 面 | DG7: 229000 | DH7: 52510 | DL7: 空冷ﾁﾗｰﾕﾆｯﾄ | DM7: UWAA375A(15HP) | DN7: 基 | DO7: 7130000 | DP7: =ROUNDUP(DO7*0.3,-2) -> 2139000 | DQ7: 0 | DT7: 膨張ﾀﾝｸ | DU7: ETU-750 ボールタップ一般型 | DV7: 台 | DW7: 815000 | DX7: 448300 | DY7: 0.5 | EB7: ｵｲﾙﾀﾝｸ | EC7: BOT-1900 | ED7: 基 | EE7: 380000 | EF7: 164280 | EG7: 1.4 | EI7: 103811000 | EJ7: 煙突ｾｯﾄ | EK7: BEP-KA1203 | EL7: ｾｯﾄ | EM7: 60400 | EN7: 20760 | EO7: 0.5 | EQ7: 2500000103 | ER7: ﾎﾟﾘﾀﾞｸﾄ | ES7: 折幅900×50m | ET7: 本 | EU7: 8590 | EV7: 3780 | EW7: 0 | EZ7: ｽﾊﾟｲﾗﾙﾀﾞｸﾄ(亜鉛) | FA7: φ350 | FB7: ｍ | FC7: 5200 | FD7: =FC7*0.65 -> 3380 | FE7: 0.18 | FO7: 051237000 | FP7: ﾊｳｽｶｵﾝｷ | FQ7: HK3030GESV | FR7: 台 | FS7: 1422000 | FT7: 537350 | FU7: 1.45 | FX7: ｴﾛﾌｨﾝ支持金具 | FY7: 3段1列 | FZ7: 本 | GA7: 24800 | GB7: 12400 | GC7: 0.3 | GE7: 051071000 | GF7: ﾊｳｽｶｵﾝｷ（LPｶﾞｽ焚き） | GG7: HK3030TFL | GH7: 台 | GI7: 1357000 | GJ7: 628610 | GK7: 1.45 | GN7: ---------- | GS7: 0 | GV7: SGPｴﾛﾌｨﾝﾁｭｰﾌﾞ | GW7: 32A 25F 2750L | GX7: 本 | GY7: =ROUND(GZ7/0.33,-3) -> 92000 | GZ7: 30200 | HA7: 0.36
B8: 7 | C8: ｼﾝｸﾛﾋｰﾀ | D8: aj3 | E8: 同上塗装補修工事 | I8: 1.2 | K8: 049829000 | L8: ﾊｳｽｶｵﾝｷ | M8: HK3030TFV | N8: 台 | O8: 1092000 | P8: 503120 | Q8: 1.45 | T8: ---------- | AA8: 025124000 | AB8: ﾊｳｽﾎﾞｲﾗ | AC8: HB-807TGA5 | AD8: 台 | AE8: 1511000 | AF8: 619670 | AG8: 1.6 | AI8: 052483000 | AJ8: ｼﾝｸﾛﾋｰﾀ | AK8: SBM100WLUJ_2（水道直結仕様） | AL8: 台 | AM8: 2730000 | AN8: 732690 | AO8: 2.3 | AQ8: 041997000 | AR8: ｵｰﾄｶﾝ | AS8: AWH-1001A | AT8: 台 | AU8: 1295000 | AV8: 399360 | AW8: 1.9 | AY8: 026708000 | AZ8: ﾈﾎﾟﾝﾌｧﾝ | BA8: FAN-302S1 | BB8: 台 | BC8: 48000 | BD8: 21150 | BE8: 0.2 | BG8: RB0000310 | BH8: 熱交換器 | BI8: ST-40(1m) | BJ8: 基 | BK8: 1019000 | BL8: 369600 | BM8: 1 | BP8: ｴﾛﾌｨﾝﾁｭｰﾌﾞ（STK 5KF） | BQ8: 32A 25F 2000L | BR8: 本 | BS8: =ROUND(BT8/0.4,-3) -> 69000 | BT8: 27500 | BU8: 0.26 | BX8: ﾌｧﾝｺｲﾙﾕﾆｯﾄ | BY8: RF-120F | BZ8: 基 | CA8: 274000 | CB8: =CA8*0.48 -> 131520 | CC8: 1.75 | CF8: ｸｰﾘﾝｸﾞﾀﾜｰ | CG8: MT-3014 | CH8: 基 | CI8: 390000 | CJ8: 214000 | CK8: 3 | CN8: 蓄熱ﾀﾝｸ | CO8: 1,500ﾘｯﾄﾙ | CP8: 基 | CQ8: 190000 | CR8: 124000 | CS8: 1 | CV8: ---------- | DC8: 103305000 | DD8: 湿度ｾﾝｻ | DE8: HUS-12 | DF8: 個 | DG8: 101800 | DH8: 24770 | DL8: 空冷ﾁﾗｰﾕﾆｯﾄ | DM8: UWAA500A(20HP) | DN8: 基 | DO8: 9160000 | DP8: =ROUNDUP(DO8*0.3,-2) -> 2748000 | DQ8: 0 | DT8: 膨張ﾀﾝｸ | DU8: ETU-1000 ボールタップ一般型 | DV8: 台 | DW8: 1055000 | DX8: 580300 | DY8: 0.5 | EB8: ｵｲﾙﾀﾝｸ | EC8: BOT- 5000 | ED8: 基 | EE8: 1448000 | EF8: 898000 | EG8: 2.4 | EI8: 104598000 | EJ8: 煙突ｾｯﾄ | EK8: BEP-KA120F | EL8: ｾｯﾄ | EM8: 72600 | EN8: 23890 | EO8: 0.5 | EQ8: 2500000104 | ER8: ﾎﾟﾘﾀﾞｸﾄ | ES8: 折幅1100×50m | ET8: 本 | EU8: 10500 | EV8: 4620 | EW8: 0 | EZ8: ｽﾊﾟｲﾗﾙﾀﾞｸﾄ(亜鉛) | FA8: φ400 | FB8: ｍ | FC8: 6300 | FD8: =FC8*0.65 -> 4095 | FE8: 0.19 | FO8: 051238000 | FP8: ﾊｳｽｶｵﾝｷ | FQ8: HK3030GFSV | FR8: 台 | FS8: 1370000 | FU8: 1.45 | FX8: ｴﾛﾌｨﾝ支持金具 | FY8: 3段2列 | FZ8: 本 | GA8: 42000 | GB8: 21000 | GC8: 0.5 | GE8: 051055000 | GF8: ﾊｳｽｶｵﾝｷ（LPｶﾞｽ焚き） | GG8: HK4030TCL | GH8: 台 | GI8: 1696000 | GJ8: 718970 | GK8: 1.7 | GM8: 038107000 | GN8: ﾋｰﾄｯﾌﾟ | GO8: HT-802TE | GP8: 台 | GQ8: 1477000 | GR8: 538650 | GS8: 1.5 | GV8: SGPｴﾛﾌｨﾝﾁｭｰﾌﾞ | GW8: 32A 25F 2000L | GX8: 本 | GY8: =ROUND(GZ8/0.33,-3) -> 86000 | GZ8: 28300 | HA8: 0.26
B9: 8 | C9: ｵｰﾄｶﾝ | D9: ar3 | E9: 同上基礎工事 | I9: 0.11 | K9: 051780000 | L9: ﾊｳｽｶｵﾝｷ | M9: HK3030TRV | N9: 台 | O9: 1396000 | P9: 610850 | Q9: 1.45 | S9: 051112000 | T9: 小型温風機 | U9: KA-125E | V9: 台 | W9: 389000 | X9: 170820 | Y9: 0.52 | AA9: 025125000 | AB9: ﾊｳｽﾎﾞｲﾗ | AC9: HB-807TGA6 | AD9: 台 | AE9: 1511000 | AF9: 617090 | AG9: 1.6 | AJ9: ----------- | AQ9: 041998000 | AR9: ｵｰﾄｶﾝ | AS9: AWH-1201A | AT9: 台 | AU9: 1484000 | AV9: 473840 | AW9: 2.05 | AY9: 049377000 | AZ9: ﾈﾎﾟﾝﾌｧﾝ | BA9: FAN-303T | BB9: 台 | BC9: 50000 | BD9: 19780 | BE9: 0.2 | BG9: RB0000311 | BH9: 熱交換器 | BI9: ST-50(1m) | BJ9: 基 | BK9: 1244000 | BL9: 451200 | BM9: 1 | BP9: ｴﾛﾌｨﾝﾁｭｰﾌﾞ（STK 5KF） | BQ9: 32A 25F 1500L | BR9: 本 | BS9: =ROUND(BT9/0.4,-3) -> 66000 | BT9: 26400 | BU9: 0.2 | BX9: ﾌｧﾝｺｲﾙﾕﾆｯﾄ | BY9: RF-3P | BZ9: 基 | CA9: 419000 | CB9: =CA9*0.48 -> 201120 | CC9: 1.5 | CF9: ｸｰﾘﾝｸﾞﾀﾜｰ | CG9: MT-4014 | CH9: 基 | CI9: 508000 | CJ9: 279000 | CK9: 3.5 | CN9: 蓄熱ﾀﾝｸ | CO9: 2,000ﾘｯﾄﾙ | CP9: 基 | CQ9: 238000 | CR9: 155000 | CS9: 1.5 | CV9: ﾗｲﾝﾎﾟﾝﾌﾟ | CW9: 50Hz φ40 0.25kW | CX9: 台 | CY9: 161000 | CZ9: =ROUND(CY9*0.53,-1) -> 85330 | DA9: 0.5 | DC9: 044702000 | DD9: 接続用ｹｰﾌﾞﾙｾｯﾄNGP109TX | DF9: 式 | DG9: 33900 | DH9: 5140 | DL9: 空冷ﾁﾗｰﾕﾆｯﾄ | DM9: UWAA630A(25HP) | DN9: 基 | DO9: 12000000 | DP9: =ROUNDUP(DO9*0.3,-2) -> 3600000 | DQ9: 0 | DT9: 同上架台 | DU9: 溶融亜鉛メッキ（SS400) 500H 100用 | DV9: 組 | DW9: 84000 | DX9: 46200 | DY9: 0.3 | EB9: ｵｲﾙﾀﾝｸ | EC9: BOT-10000 | ED9: 基 | EE9: 1980000 | EF9: 1230000 | EG9: 3.5 | EI9: 104719000 | EJ9: 煙突ｾｯﾄ | EK9: BEP-20T1504 | EL9: ｾｯﾄ | EM9: 72800 | EN9: 23890 | EO9: 0.7 | EQ9: RE0000378 | ER9: ﾎﾟﾘﾀﾞｸﾄ（局所施用） | ES9: 折幅160×200m | ET9: 本 | EU9: 45300 | EV9: 22770 | EW9: 0 | EZ9: ｽﾊﾟｲﾗﾙﾀﾞｸﾄ(亜鉛) | FA9: φ500 | FB9: ｍ | FC9: 7900 | FD9: =FC9*0.65 -> 5135 | FE9: 0.2 | FP9: ---------- | GE9: 051065000 | GF9: ﾊｳｽｶｵﾝｷ（LPｶﾞｽ焚き） | GG9: HK4030TEL | GH9: 台 | GI9: 1752000 | GJ9: 748140 | GK9: 1.7 | GM9: 038108000 | GN9: ﾋｰﾄｯﾌﾟ | GO9: HT-802TF | GP9: 台 | GQ9: 1477000 | GR9: 591160 | GS9: 1.5 | GV9: SGPｴﾛﾌｨﾝﾁｭｰﾌﾞ | GW9: 32A 25F 1500L | GX9: 本 | GY9: =ROUND(GZ9/0.33,-3) -> 82000 | GZ9: 27100 | HA9: 0.2
B10: 9 | C10: ﾋｰﾄｯﾌﾟ・ｶﾜｲﾀｰ | D10: gn3 | E10: 同上組立取付工事 | K10: 049830000 | L10: ﾊｳｽｶｵﾝｷ | M10: HK4030TCV | N10: 台 | O10: 1424000 | P10: 593740 | Q10: 1.7 | S10: 051114000 | T10: 小型温風機 | U10: KA-205E | V10: 台 | W10: 450000 | X10: 176880 | Y10: 0.7 | AA10: 025415000 | AB10: ﾊｳｽﾎﾞｲﾗ | AC10: HB-1007TA | AD10: 台 | AE10: 2145000 | AF10: 761850 | AG10: 1.7 | AI10: 052489000 | AJ10: ｼﾝｸﾛﾋｰﾀ | AK10: SBM150WNT_8 | AL10: 台 | AM10: 3494000 | AN10: 933310 | AO10: 3 | AQ10: 041999000 | AR10: ｵｰﾄｶﾝ | AS10: AWH-1501A | AT10: 台 | AU10: 1729000 | AV10: 475170 | AW10: 2.3 | AY10: 105493000 | AZ10: ﾈﾎﾟﾝﾌｧﾝ | BA10: FAN-400T | BB10: 台 | BC10: 55000 | BD10: 26720 | BE10: 0.2 | BH10: ---------- | BP10: ｴﾛﾌｨﾝﾁｭｰﾌﾞ（STK 5KF） | BQ10: 32A 25F 1000L | BR10: 本 | BS10: =ROUND(BT10/0.4,-3) -> 64000 | BT10: 25500 | BU10: 0.13 | BX10: ﾌｧﾝｺｲﾙﾕﾆｯﾄ | BY10: RF-5P | BZ10: 基 | CA10: 520000 | CB10: =CA10*0.48 -> 249600 | CC10: 1.5 | CF10: ｸｰﾘﾝｸﾞﾀﾜｰ | CG10: MT-5014 | CH10: 基 | CI10: 619000 | CJ10: 340000 | CK10: 3.5 | CN10: 蓄熱ﾀﾝｸ | CO10: 3,000ﾘｯﾄﾙ | CP10: 基 | CQ10: 335000 | CR10: 218000 | CS10: 2 | CV10: ﾗｲﾝﾎﾟﾝﾌﾟ | CW10: 50Hz φ40 0.4kW | CX10: 台 | CY10: 181000 | CZ10: =ROUND(CY10*0.53,-1) -> 95930 | DA10: 0.5 | DD10: ﾌｨﾙﾀﾄﾞﾗｲﾔ | DF10: 個 | DG10: 15000 | DH10: 9010 | DI10: 0 | DL10: 空冷ﾁﾗｰﾕﾆｯﾄ | DM10: UWAA750A(30HP) | DN10: 基 | DO10: 14420000 | DP10: =ROUNDUP(DO10*0.3,-2) -> 4326000 | DQ10: 0 | DT10: 同上架台 | DU10: 溶融亜鉛メッキ（SS400) 500H 200用 | DV10: 組 | DW10: 90000 | DX10: 49500 | DY10: 0.3 | EB10: ｵｲﾙﾀﾝｸ | EC10: BOT-15000 | ED10: 基 | EE10: 2470000 | EF10: 1530000 | EG10: 4.4 | EI10: 102384000 | EJ10: 煙突ｾｯﾄ | EK10: BEP-20T2252 | EL10: ｾｯﾄ | EM10: 108400 | EN10: 37760 | EO10: 0.7 | ER10: ---------- | EZ10: ｽﾊﾟｲﾗﾙﾀﾞｸﾄ(亜鉛) | FA10: φ550 | FB10: ｍ | FC10: 8700 | FD10: =FC10*0.65 -> 5655 | FE10: 0.2 | FO10: 051239000 | FP10: ﾊｳｽｶｵﾝｷ | FQ10: HK4030GCSV | FR10: 台 | FS10: 1899000 | FT10: 619800 | FU10: 1.7 | GE10: 051073000 | GF10: ﾊｳｽｶｵﾝｷ（LPｶﾞｽ焚き） | GG10: HK4030TFL | GH10: 台 | GI10: 1655000 | GJ10: 730900 | GK10: 1.7 | GM10: 038111000 | GN10: ﾋｰﾄｯﾌﾟ | GO10: HT-1202TE | GP10: 台 | GQ10: 1911000 | GR10: 725980 | GS10: 2 | GV10: SGPｴﾛﾌｨﾝﾁｭｰﾌﾞ | GW10: 32A 25F 1000L | GX10: 本 | GY10: =ROUND(GZ10/0.33,-3) -> 78000 | GZ10: 25900 | HA10: 0.13
B11: 10 | C11: 煙道・煙突関連部材・掃除具ｾｯﾄ | D11: ej3 | E11: ---------- | K11: 049831000 | L11: ﾊｳｽｶｵﾝｷ | M11: HK4030TEV | N11: 台 | O11: 1478000 | P11: 620960 | Q11: 1.7 | S11: 051116000 | T11: 小型温風機 | U11: KA-325E | V11: 台 | W11: 545000 | X11: 215850 | Y11: 0.9 | AA11: 025417000 | AB11: ﾊｳｽﾎﾞｲﾗ | AC11: HB-2007TA | AD11: 台 | AE11: 2735000 | AF11: 975890 | AG11: 2.75 | AI11: 052490000 | AJ11: ｼﾝｸﾛﾋｰﾀ | AK11: SBM150WMT_8 | AL11: 台 | AM11: 3494000 | AN11: 931760 | AO11: 3 | AQ11: 042000000 | AR11: ｵｰﾄｶﾝ | AS11: AWH-1801A | AT11: 台 | AU11: 1900000 | AV11: 504250 | AW11: 2.6 | AY11: 031741000 | AZ11: ﾈﾎﾟﾝVﾌｧﾝ | BA11: NVF-350T | BB11: 台 | BC11: 111000 | BD11: 43040 | BG11: RB0000313 | BH11: 熱交換器 | BI11: ST-3(2m) | BJ11: 基 | BK11: 358000 | BL11: 129600 | BM11: 1 | BP11: ---------- | BX11: ﾌｧﾝｺｲﾙﾕﾆｯﾄ | BY11: RF-8P | BZ11: 基 | CA11: 620000 | CB11: =CA11*0.48 -> 297600 | CC11: 2 | CF11: ｸｰﾘﾝｸﾞﾀﾜｰ | CG11: MT-6014 | CH11: 基 | CI11: 746000 | CJ11: 410000 | CK11: 3.5 | CV11: ﾗｲﾝﾎﾟﾝﾌﾟ | CW11: 50Hz φ40 0.75kW | CX11: 台 | CY11: 220000 | CZ11: =ROUND(CY11*0.53,-1) -> 116600 | DA11: 0.5 | DD11: ---------- | DL11: ---------- | DT11: 同上架台 | DU11: 溶融亜鉛メッキ（SS400) 500H 300用 | DV11: 組 | DW11: 102000 | DX11: 56100 | DY11: 0.3 | EB11: ｵｲﾙﾀﾝｸ | EC11: BOT-20000 | ED11: 基 | EE11: 2600000 | EF11: 1613000 | EG11: 5.1 | EJ11: 煙突ｾｯﾄ | EK11: φ250*3本+Ｌ+Pﾄｯﾌﾟ | EL11: ｾｯﾄ | EM11: 219900 | EN11: 109950 | EO11: 1.5 | EQ11: RE0000177 | ER11: ﾊﾟﾜｰﾀﾞｸﾄ | ES11: 折幅400×100m | ET11: 本 | EU11: 20400 | EV11: 9950 | EW11: 0 | EZ11: ｽﾊﾟｲﾗﾙﾀﾞｸﾄ(亜鉛) | FA11: φ600 | FB11: ｍ | FC11: 9500 | FD11: =FC11*0.65 -> 6175 | FE11: 0.24 | FO11: 051240000 | FP11: ﾊｳｽｶｵﾝｷ | FQ11: HK4030GESV | FR11: 台 | FS11: 1956000 | FT11: 650910 | FU11: 1.7 | GE11: 051057000 | GF11: ﾊｳｽｶｵﾝｷ（LPｶﾞｽ焚き） | GG11: HK5030TCL | GH11: 台 | GI11: 1902000 | GJ11: 856000 | GK11: 2 | GM11: 038112000 | GN11: ﾋｰﾄｯﾌﾟ | GO11: HT-1202TF | GP11: 台 | GQ11: 1911000 | GR11: 737980 | GS11: 2 | GV11: ----------
B12: 11 | C12: ﾎﾟﾘﾀﾞｸﾄ・ｸﾛｽﾗﾑﾀﾞｸﾄ | D12: er3 | E12: 機器搬入据付工事 | K12: 049832000 | L12: ﾊｳｽｶｵﾝｷ | M12: HK4030TFV | N12: 台 | O12: 1386000 | P12: 603330 | Q12: 1.7 | S12: 051118000 | T12: 小型温風機 | U12: KA-325TE | V12: 台 | W12: 596000 | X12: 228490 | Y12: 0.9 | AA12: 025418000 | AB12: ﾊｳｽﾎﾞｲﾗ | AC12: HB-3007TA | AD12: 台 | AE12: 3278000 | AF12: 1208630 | AG12: 3.4 | AI12: 052491000 | AJ12: ｼﾝｸﾛﾋｰﾀ | AK12: SBM150WLT_8 | AL12: 台 | AM12: 3494000 | AN12: 933310 | AO12: 3 | AQ12: 042001000 | AR12: ｵｰﾄｶﾝ | AS12: AWH-2001A | AT12: 台 | AU12: 2032000 | AV12: 499220 | AW12: 2.75 | AZ12: ---------- | BG12: RB0000314 | BH12: 熱交換器 | BI12: ST-5(2m) | BJ12: 基 | BK12: 450000 | BL12: 163200 | BM12: 1 | BP12: ｴﾛﾌｨﾝﾁｭｰﾌﾞ（STK 5KF） | BQ12: 32A 32F 5500L | BR12: 本 | BS12: =ROUND(BT12/0.4,-3) -> 93000 | BT12: 37000 | BU12: 0.72 | BX12: ﾌｧﾝｺｲﾙﾕﾆｯﾄ | BY12: RF-10P | BZ12: 基 | CA12: 715000 | CB12: =CA12*0.48 -> 343200 | CC12: 2 | CF12: ｸｰﾘﾝｸﾞﾀﾜｰ | CG12: MT-8014 | CH12: 基 | CI12: 997000 | CJ12: 548000 | CK12: 3.5 | CV12: ﾗｲﾝﾎﾟﾝﾌﾟ | CW12: 50Hz φ40 1.5kW | CX12: 台 | CY12: 294000 | CZ12: =ROUND(CY12*0.53,-1) -> 155820 | DA12: 0.6 | DC12: 048822000 | DD12: 誰でもﾋｰﾎﾟﾝ | DE12: EHP61(ｾｯﾄ) | DF12: ｾｯﾄ | DG12: 597000 | DH12: - | DI12: 1.6 | DL12: 空冷ﾋｰﾄﾎﾟﾝﾌﾟﾁﾗｰﾕﾆｯﾄ | DM12: UWYA125A(5HP) | DN12: 基 | DO12: 3820000 | DP12: =ROUNDUP(DO12*0.3,-2) -> 1146000 | DQ12: 0 | DT12: 同上架台 | DU12: 溶融亜鉛メッキ（SS400) 500H 500用 | DV12: 組 | DW12: 113000 | DX12: 62200 | DY12: 0.5 | EB12: ---------- | EJ12: 煙突ｾｯﾄ | EK12: φ300*3本+L+Pﾄｯﾌﾟ | EL12: ｾｯﾄ | EM12: 301000 | EN12: 150500 | EO12: 1.5 | EQ12: RE0000178 | ER12: ﾊﾟﾜｰﾀﾞｸﾄ | ES12: 折幅475×100m | ET12: 本 | EU12: 22800 | EV12: 11350 | EW12: 0 | EZ12: ｽﾊﾟｲﾗﾙﾀﾞｸﾄ(SUS) | FA12: φ200 | FB12: ｍ | FC12: 15600 | FD12: =FC12*0.65 -> 10140 | FE12: 0.16 | FO12: 051241000 | FP12: ﾊｳｽｶｵﾝｷ | FQ12: HK4030GFSV | FR12: 台 | FS12: 1856000 | FU12: 1.7 | GE12: 051067000 | GF12: ﾊｳｽｶｵﾝｷ（LPｶﾞｽ焚き） | GG12: HK5030TEL | GH12: 台 | GI12: 1972000 | GJ12: 906810 | GK12: 2 | GN12: ---------- | GV12: SGPｴﾛﾌｨﾝﾁｭｰﾌﾞ | GW12: 32A 32F 5500L | GX12: 本 | GY12: =ROUND(GZ12/0.33,-3) -> 119000 | GZ12: 39300 | HA12: 0.72
B13: 12 | C13: ｸﾞﾘｰﾝｿｰﾗ・ﾀﾞｲﾚｸﾄﾌｧﾝ | D13: az3 | E13: 機器取付工事 | K13: 051505000 | L13: ﾊｳｽｶｵﾝｷ | M13: HK4030FRV | N13: 台 | O13: 1746000 | P13: 752030 | Q13: 1.7 | S13: 051120000 | T13: 小型温風機 | U13: KA-405TE | V13: 台 | W13: 692000 | X13: 259200 | Y13: 1 | AA13: 025421000 | AB13: ﾊｳｽﾎﾞｲﾗ | AC13: HB-4007TA | AD13: 台 | AE13: 3581000 | AF13: 1317910 | AG13: 4 | AI13: 046046000 | AJ13: ｼﾝｸﾛﾋｰﾀ | AK13: SBM150WNTJ_2（水道直結仕様） | AL13: 台 | AM13: 3736000 | AN13: 985820 | AO13: 3 | AR13: ---------- | AY13: 017836000 | AZ13: ﾀﾞｸﾄﾌｧﾝ | BA13: DF-450T | BB13: 台 | BC13: 221000 | BD13: 76770 | BE13: 0.5 | BG13: RB0000315 | BH13: 熱交換器 | BI13: ST-8(2m) | BJ13: 基 | BK13: 623000 | BL13: 225600 | BM13: 1.2 | BP13: ｴﾛﾌｨﾝﾁｭｰﾌﾞ（STK 5KF） | BQ13: 32A 32F 4000L | BR13: 本 | BS13: =ROUND(BT13/0.4,-3) -> 84000 | BT13: 33500 | BU13: 0.52 | BX13: ﾌｧﾝｺｲﾙﾕﾆｯﾄ | BY13: RF-15P | BZ13: 基 | CA13: 1060000 | CB13: =CA13*0.48 -> 508800 | CC13: 2.5 | CF13: ｸｰﾘﾝｸﾞﾀﾜｰ | CG13: MT-10014 | CH13: 基 | CI13: 1273000 | CJ13: 700000 | CK13: 3.5 | CV13: ﾗｲﾝﾎﾟﾝﾌﾟ | CW13: 50Hz φ40 2.2kW | CX13: 台 | CY13: 327000 | CZ13: =ROUND(CY13*0.53,-1) -> 173310 | DA13: 0.6 | DC13: 028329000 | DD13: 誰でもﾋｰﾎﾟﾝ(ﾁｬﾝﾊﾞｰﾀｲﾌﾟ) | DE13: EHP61C-N（室内機） | DF13: 台 | DG13: 494000 | DH13: 153910 | DI13: 1.6 | DL13: 空冷ﾋｰﾄﾎﾟﾝﾌﾟﾁﾗｰﾕﾆｯﾄ | DM13: UWYA190A(8HP) | DN13: 基 | DO13: 4920000 | DP13: =ROUNDUP(DO13*0.3,-2) -> 1476000 | DQ13: 0 | DT13: 同上架台 | DU13: 溶融亜鉛メッキ（SS400) 500H 750用 | DV13: 組 | DW13: 118000 | DX13: 64900 | DY13: 0.5 | EA13: 014963000 | EB13: 消火器 | EC13: ABC-10形 | ED13: 本 | EE13: 26200 | EF13: 4780 | EG13: 0.1 | EJ13: 煙突ｾｯﾄ | EK13: φ350*3本+L+Pﾄｯﾌﾟ | EL13: ｾｯﾄ | EM13: 378600 | EN13: 189300 | EO13: 1.5 | EQ13: RE0000180 | ER13: ﾊﾟﾜｰﾀﾞｸﾄ | ES13: 折幅550×100m | ET13: 本 | EU13: 27600 | EV13: 12950 | EW13: 0 | EZ13: ｽﾊﾟｲﾗﾙﾀﾞｸﾄ(SUS) | FA13: φ225 | FB13: ｍ | FC13: 17600 | FD13: =FC13*0.65 -> 11440 | FE13: 0.18 | FP13: ---------- | GE13: 051075000 | GF13: ﾊｳｽｶｵﾝｷ（LPｶﾞｽ焚き） | GG13: HK5030TFL | GH13: 台 | GI13: 1852000 | GJ13: 824100 | GK13: 2 | GM13: 039196000 | GN13: ｶﾜｲﾀｰ | GO13: KT1026TPF3 | GP13: 台 | GQ13: 2851000 | GR13: 838610 | GS13: 2 | GV13: SGPｴﾛﾌｨﾝﾁｭｰﾌﾞ | GW13: 32A 32F 4000L | GX13: 本 | GY13: =ROUND(GZ13/0.33,-3) -> 107000 | GZ13: 35200 | HA13: 0.52
B14: 13 | C14: 熱交換器 | D14: bh3 | E14: 機器架台及び据付工事 | K14: 051781000 | L14: ﾊｳｽｶｵﾝｷ | M14: HK4030GRV | N14: 台 | O14: 1746000 | P14: 720010 | Q14: 1.7 | T14: ---------- | AB14: ----------- | AI14: 052492000 | AJ14: ｼﾝｸﾛﾋｰﾀ | AK14: SBM150WMTJ_3（水道直結仕様） | AL14: 台 | AM14: 3736000 | AN14: 994720 | AO14: 3 | AQ14: 042002000 | AR14: ｵｰﾄｶﾝ | AS14: AWH-501SA | AT14: 台 | AU14: 1000000 | AV14: 310890 | AW14: 1.3 | AY14: 018835000 | AZ14: φ300吹出口ﾌﾗﾝｼﾞｾｯﾄ | BA14: BFS-DFφ300 | BB14: 台 | BC14: 13100 | BD14: 3830 | BG14: RB0000316 | BH14: 熱交換器 | BI14: ST-10(2m) | BJ14: 基 | BK14: 847000 | BL14: 307200 | BM14: 1.5 | BP14: ｴﾛﾌｨﾝﾁｭｰﾌﾞ（STK 5KF） | BQ14: 32A 32F 3500L | BR14: 本 | BS14: =ROUND(BT14/0.4,-3) -> 80000 | BT14: 32100 | BU14: 0.46 | BX14: ﾌｧﾝｺｲﾙﾕﾆｯﾄ | BY14: RF-20P | BZ14: 基 | CA14: 1420000 | CB14: =CA14*0.48 -> 681600 | CC14: 2.5 | CV14: ---------- | DC14: 036831000 | DD14: 誰でもﾋｰﾎﾟﾝ | DE14: EHP61G（室外機） | DF14: 台 | DG14: 585000 | DH14: 177970 | DI14: 1.6 | DL14: 空冷ﾋｰﾄﾎﾟﾝﾌﾟﾁﾗｰﾕﾆｯﾄ | DM14: UWYA250A(10HP) | DN14: 基 | DO14: 5830000 | DP14: =ROUNDUP(DO14*0.3,-2) -> 1749000 | DQ14: 0 | DT14: 同上架台 | DU14: 溶融亜鉛メッキ（SS400) 500H 1000用 | DV14: 組 | DW14: 168000 | DX14: 92400 | DY14: 0.5 | EB14: 消火器 | EC14: ABC-50形 | ED14: 基 | EE14: 85000 | EF14: 43500 | EG14: 0.1 | EJ14: ---------- | EQ14: RE0000174 | ER14: ﾊﾟﾜｰﾀﾞｸﾄ | ES14: 折幅630×50m | ET14: 本 | EU14: 18000 | EV14: 8150 | EW14: 0 | EZ14: ｽﾊﾟｲﾗﾙﾀﾞｸﾄ(SUS) | FA14: φ250 | FB14: ｍ | FC14: 19500 | FD14: =FC14*0.65 -> 12675 | FE14: 0.18 | FO14: 051242000 | FP14: ﾊｳｽｶｵﾝｷ | FQ14: HK5030GCSV | FR14: 台 | FS14: 2114000 | FT14: 724930 | FU14: 2 | GE14: 051059000 | GF14: ﾊｳｽｶｵﾝｷ（LPｶﾞｽ焚き） | GG14: HK6030TCL | GH14: 台 | GI14: 2107000 | GJ14: 912260 | GK14: 2.2 | GM14: 039197000 | GN14: ｶﾜｲﾀｰ | GO14: KT1026TPG3 | GP14: 台 | GQ14: 2851000 | GR14: 854610 | GS14: 2 | GV14: SGPｴﾛﾌｨﾝﾁｭｰﾌﾞ | GW14: 32A 32F 3500L | GX14: 本 | GY14: =ROUND(GZ14/0.33,-3) -> 102000 | GZ14: 33600 | HA14: 0.46
B15: 14 | C15: STKｴﾛﾌｨﾝﾁｭｰﾌﾞ | D15: bp3 | E15: 機器架台工事 | K15: 051782000 | L15: ﾊｳｽｶｵﾝｷ | M15: HK4030TYV | N15: 台 | O15: 1722000 | P15: 762530 | Q15: 1.7 | S15: 042809000 | T15: 小型温風機（LPガス焚き） | U15: KA-325EL | V15: 台 | W15: 935000 | X15: 373890 | Y15: 0.9 | AI15: 052493000 | AJ15: ｼﾝｸﾛﾋｰﾀ | AK15: SBM150WLTJ_3（水道直結仕様） | AL15: 台 | AM15: 3736000 | AN15: 994590 | AO15: 3 | AQ15: 042003000 | AR15: ｵｰﾄｶﾝ | AS15: AWH-601SA | AT15: 台 | AU15: 1039000 | AV15: 313300 | AW15: 1.4 | AY15: 018834000 | AZ15: φ400吹出口ﾌﾗﾝｼﾞｾｯﾄ | BA15: BFS-DFφ400 | BB15: 台 | BC15: 15700 | BD15: 3250 | BG15: RB0000317 | BH15: 熱交換器 | BI15: ST-20(2m) | BJ15: 基 | BK15: 1032000 | BL15: 374400 | BM15: 1.75 | BP15: ｴﾛﾌｨﾝﾁｭｰﾌﾞ（STK 5KF） | BQ15: 32A 32F 3000L | BR15: 本 | BS15: =ROUND(BT15/0.4,-3) -> 77000 | BT15: 30900 | BU15: 0.4 | CV15: ﾗｲﾝﾎﾟﾝﾌﾟ | CW15: 50Hz φ50 0.4kW | CX15: 台 | CY15: 192000 | CZ15: =ROUND(CY15*0.53,-1) -> 101760 | DA15: 0.5 | DC15: 025678000 | DD15: 操作盤 | DE15: EHPOB (EHP61用) | DF15: 面 | DG15: 31800 | DH15: 10700 | DI15: 1.6 | DL15: 空冷ﾋｰﾄﾎﾟﾝﾌﾟﾁﾗｰﾕﾆｯﾄ | DM15: UWYA375A(15HP) | DN15: 基 | DO15: 8880000 | DP15: =ROUNDUP(DO15*0.3,-2) -> 2664000 | DQ15: 0 | DT15: ---------- | EA15: 174001000 | EB15: 格納箱 | EC15: ABC-10用 | ED15: 個 | EE15: 11300 | EF15: 2710 | EG15: 0.2 | EI15: 050735000 | EJ15: 煙室ｾｯﾄ | EK15: ES-2330 | EL15: ｾｯﾄ | EM15: 119000 | EN15: 35870 | EO15: 0.5 | EQ15: RE0000175 | ER15: ﾊﾟﾜｰﾀﾞｸﾄ | ES15: 折幅900×50m | ET15: 本 | EU15: 21600 | EV15: 10650 | EW15: 0 | EZ15: ｽﾊﾟｲﾗﾙﾀﾞｸﾄ(SUS) | FA15: φ300 | FB15: ｍ | FC15: 26900 | FD15: =FC15*0.65 -> 17485 | FE15: 0.18 | FO15: 051243000 | FP15: ﾊｳｽｶｵﾝｷ | FQ15: HK5030GESV | FR15: 台 | FS15: 2177000 | FT15: 0 | FU15: 2 | GE15: 051069000 | GF15: ﾊｳｽｶｵﾝｷ（LPｶﾞｽ焚き） | GG15: HK6030TEL | GH15: 台 | GI15: 2205000 | GJ15: 974480 | GK15: 2.2 | GM15: 039198000 | GN15: ｶﾜｲﾀｰ | GO15: KT1526TPF3 | GP15: 台 | GQ15: 3211000 | GR15: 857060 | GS15: 2.5 | GV15: SGPｴﾛﾌｨﾝﾁｭｰﾌﾞ | GW15: 32A 32F 3000L | GX15: 本 | GY15: =ROUND(GZ15/0.33,-3) -> 98000 | GZ15: 32200 | HA15: 0.4
B16: 15 | C16: SGPｴﾛﾌｨﾝﾁｭｰﾌﾞ | D16: ｇv3 | E16: 機器基礎工事 | K16: 049833000 | L16: ﾊｳｽｶｵﾝｷ | M16: HK5030TCV | N16: 台 | O16: 1620000 | P16: 701210 | Q16: 2 | S16: 042793000 | T16: 小型温風機（13Aガス焚き） | U16: KA-325EN | V16: 台 | W16: 935000 | X16: 373630 | Y16: 0.9 | AJ16: ----------- | AQ16: 042004000 | AR16: ｵｰﾄｶﾝ | AS16: AWH-701SA | AT16: 台 | AU16: 1116000 | AV16: 313300 | AW16: 1.55 | AY16: 018836000 | AZ16: φ400ﾌﾗﾝｼﾞ取付板ｾｯﾄ | BA16: BFS-DF400S | BB16: 枚 | BC16: 13500 | BD16: 1990 | BH16: ---------- | BP16: ｴﾛﾌｨﾝﾁｭｰﾌﾞ（STK 5KF） | BQ16: 32A 32F 2750L | BR16: 本 | BS16: =ROUND(BT16/0.4,-3) -> 76000 | BT16: 30200 | BU16: 0.36 | CV16: ﾗｲﾝﾎﾟﾝﾌﾟ | CW16: 50Hz φ50 0.75kW | CX16: 台 | CY16: 223000 | CZ16: =ROUND(CY16*0.53,-1) -> 118190 | DA16: 0.6 | DC16: 027332000 | DD16: 送風機増速盤 | DE16: EHPFC (50Hz電源用) | DF16: 面 | DG16: 97300 | DH16: 35000 | DI16: 1.6 | DL16: 空冷ﾋｰﾄﾎﾟﾝﾌﾟﾁﾗｰﾕﾆｯﾄ | DM16: UWYA500A(20HP) | DN16: 基 | DO16: 11400000 | DP16: =ROUNDUP(DO16*0.3,-2) -> 3420000 | DQ16: 0 | DT16: 膨張ﾀﾝｸ | DU16: HUW-40 ボールタップ一般型 | DV16: 台 | DW16: 352000 | DX16: 193600 | DY16: 0.5 | EB16: 格納箱 | EC16: ABC-50用 | ED16: 個 | EE16: 63000 | EF16: 25000 | EG16: 0.3 | EI16: 050736000 | EJ16: 煙室ｾｯﾄ | EK16: ES-4030 | EL16: ｾｯﾄ | EM16: 126000 | EN16: 40000 | EO16: 0.5 | EQ16: RE0000176 | ER16: ﾊﾟﾜｰﾀﾞｸﾄ | ES16: 折幅1100×50m | ET16: 本 | EU16: 25100 | EV16: 12550 | EW16: 0 | EZ16: ｽﾊﾟｲﾗﾙﾀﾞｸﾄ(SUS) | FA16: φ350 | FB16: ｍ | FC16: 36300 | FD16: =FC16*0.65 -> 23595 | FE16: 0.19 | FO16: 051244000 | FP16: ﾊｳｽｶｵﾝｷ | FQ16: HK5030GFSV | FR16: 台 | FS16: 2061000 | FT16: 692910 | FU16: 2 | GE16: 051077000 | GF16: ﾊｳｽｶｵﾝｷ（LPｶﾞｽ焚き） | GG16: HK6030TFL | GH16: 台 | GI16: 2051000 | GJ16: 875180 | GK16: 2.2 | GM16: 105850000 | GN16: ｶﾜｲﾀｰ | GO16: KT1526TPHF | GP16: 台 | GQ16: 2701000 | GR16: 779130 | GS16: 2.5 | GV16: SGPｴﾛﾌｨﾝﾁｭｰﾌﾞ | GW16: 32A 32F 2750L | GX16: 本 | GY16: =ROUND(GZ16/0.33,-3) -> 95000 | GZ16: 31400 | HA16: 0.36
B17: 16 | C17: ｴﾛﾌｨﾝ支持金具 | D17: fx3 | E17: 煙突支持取付工事 | K17: 049834000 | L17: ﾊｳｽｶｵﾝｷ | M17: HK5030TEV | N17: 台 | O17: 1680000 | P17: 752540 | Q17: 2 | S17: 042812000 | T17: 小型温風機（LPガス焚き） | U17: KA-325TEL | V17: 台 | W17: 948000 | X17: 386790 | Y17: 0.9 | AI17: 046049000 | AJ17: ｼﾝｸﾛﾋｰﾀ | AK17: SBM150HNT_4 13A 高温出湯 | AL17: 台 | AM17: 3875000 | AN17: 939890 | AO17: 3 | AQ17: 042005000 | AR17: ｵｰﾄｶﾝ | AS17: AWH-801SA | AT17: 台 | AU17: 1185000 | AV17: 379920 | AW17: 1.65 | AY17: 018837000 | AZ17: 架台ｾｯﾄ | BA17: BKD-DF | BB17: ｾｯﾄ | BC17: 67900 | BD17: 19480 | BG17: 103419000 | BH17: 熱交換器ｺｲﾙ | BI17: BNC-150 | BJ17: 基 | BK17: 121700 | BL17: 33020 | BM17: 0.5 | BP17: ｴﾛﾌｨﾝﾁｭｰﾌﾞ（STK 5KF） | BQ17: 32A 32F 2000L | BR17: 本 | BS17: =ROUND(BT17/0.4,-3) -> 71000 | BT17: 28500 | BU17: 0.26 | CV17: ﾗｲﾝﾎﾟﾝﾌﾟ | CW17: 50Hz φ50 1.5kW | CX17: 台 | CY17: 291000 | CZ17: =ROUND(CY17*0.53,-1) -> 154230 | DA17: 0.7 | DC17: 019031000 | DD17: ﾌｧﾝﾀｲﾏｾｯﾄ | DE17: EHPCX | DF17: 式 | DG17: 23100 | DH17: 3200 | DL17: 空冷ﾋｰﾄﾎﾟﾝﾌﾟﾁﾗｰﾕﾆｯﾄ | DM17: UWYA630A(25HP) | DN17: 基 | DO17: 14870000 | DP17: =ROUNDUP(DO17*0.3,-2) -> 4461000 | DQ17: 0 | DT17: 膨張ﾀﾝｸ | DU17: HUW-60 ボールタップ一般型 | DV17: 台 | DW17: 376000 | DX17: 206800 | DY17: 0.75 | EB17: 危険物看板 | EC17: 火気厳禁他1点 | ED17: ｾｯﾄ | EE17: 4980 | EF17: 1560 | EG17: 0.5 | EI17: 050737000 | EJ17: 煙室ｾｯﾄ | EK17: ES-5630 | EL17: ｾｯﾄ | EM17: 145000 | EN17: 52380 | EO17: 0.5 | EQ17: RE0000181 | ER17: ﾊﾟﾜｰﾀﾞｸﾄ | ES17: 折幅400×200m(0.07) | ET17: 本 | EU17: 26300 | EV17: 12950 | EW17: 0 | EZ17: ｽﾊﾟｲﾗﾙﾀﾞｸﾄ(SUS) | FA17: φ400 | FB17: ｍ | FC17: 49000 | FD17: =FC17*0.65 -> 31850 | FE17: 0.19 | FP17: ---------- | GF17: ﾊｳｽｶｵﾝｷ（LPｶﾞｽ焚き） | GG17: HK8030TCL | GH17: 台 | GI17: 2900000 | GJ17: 1258610 | GK17: 2.8 | GM17: 039003000 | GN17: ｶﾜｲﾀｰ | GO17: KT1526TPFW | GP17: 台 | GQ17: 3312000 | GR17: 959890 | GS17: 2.5 | GV17: SGPｴﾛﾌｨﾝﾁｭｰﾌﾞ | GW17: 32A 32F 2000L | GX17: 本 | GY17: =ROUND(GZ17/0.33,-3) -> 89000 | GZ17: 29300 | HA17: 0.26
B18: 17 | C18: ﾌｧﾝｺｲﾙﾕﾆｯﾄ | D18: bx3 | E18: 煙突取付工事 | K18: 049835000 | L18: ﾊｳｽｶｵﾝｷ | M18: HK5030TFV | N18: 台 | O18: 1572000 | P18: 668670 | Q18: 2 | S18: 042810000 | T18: 小型温風機（13Aガス焚き） | U18: KA-325TEN | V18: 台 | W18: 948000 | X18: 386790 | Y18: 0.9 | AI18: 052495000 | AJ18: ｼﾝｸﾛﾋｰﾀ | AK18: SBM150HNT_5 13A 高温出湯 | AL18: 台 | AM18: 3875000 | AN18: 950730 | AO18: 3 | AQ18: 042006000 | AR18: ｵｰﾄｶﾝ | AS18: AWH-901SA | AT18: 台 | AU18: 1242000 | AV18: 382330 | AW18: 1.75 | AY18: 018838000 | AZ18: ﾁｬﾝﾊﾞﾎﾞｯｸｽ | BA18: BCB-DF | BB18: 台 | BC18: 109200 | BD18: 20510 | BP18: ｴﾛﾌｨﾝﾁｭｰﾌﾞ（STK 5KF） | BQ18: 32A 32F 1500L | BR18: 本 | BS18: =ROUND(BT18/0.4,-3) -> 68000 | BT18: 27300 | BU18: 0.2 | CV18: ﾗｲﾝﾎﾟﾝﾌﾟ | CW18: 50Hz φ50 2.2kW | CX18: 台 | CY18: 327000 | CZ18: =ROUND(CY18*0.53,-1) -> 173310 | DA18: 0.7 | DC18: 019037000 | DD18: ﾈﾎﾟﾝｻｰﾓｾｯﾄ | DE18: EHPCX | DF18: 式 | DG18: 33500 | DH18: 4360 | DL18: 空冷ﾋｰﾄﾎﾟﾝﾌﾟﾁﾗｰﾕﾆｯﾄ | DM18: UWYA750A(30HP) | DN18: 基 | DO18: 17870000 | DP18: =ROUNDUP(DO18*0.3,-2) -> 5361000 | DQ18: 0 | DT18: 膨張ﾀﾝｸ | DU18: HUW-80 ボールタップ一般型 | DV18: 台 | DW18: 431000 | DX18: 237100 | DY18: 1 | EB18: 同上取付金具 | EC18: (取付を含む) | ED18: 式 | EE18: 25000 | EF18: 10000 | EG18: 0.5 | EI18: 050738000 | EJ18: 煙室ｾｯﾄ | EK18: ES-8030 | EL18: ｾｯﾄ | EM18: 147000 | EN18: 63990 | EO18: 0.7 | EQ18: RE0000182 | ER18: ﾊﾟﾜｰﾀﾞｸﾄ | ES18: 折幅475×200m(0.07) | ET18: 本 | EU18: 29800 | EV18: 14900 | EW18: 0 | EZ18: ｽﾊﾟｲﾗﾙﾀﾞｸﾄ(SUS) | FA18: φ450 | FB18: ｍ | FC18: 52800 | FD18: =FC18*0.65 -> 34320 | FE18: 0.19 | FO18: 051245000 | FP18: ﾊｳｽｶｵﾝｷ | FQ18: HK6030GCSV | FR18: 台 | FS18: 2328000 | FT18: 746190 | FU18: 2.2 | GF18: ---------- | GM18: 007369000 | GN18: ｶﾜｲﾀｰ | GO18: KT1526TPHFW | GP18: 台 | GQ18: 2777000 | GR18: 882220 | GS18: 2.5 | GV18: SGPｴﾛﾌｨﾝﾁｭｰﾌﾞ | GW18: 32A 32F 1500L | GX18: 本 | GY18: =ROUND(GZ18/0.33,-3) -> 85000 | GZ18: 27900 | HA18: 0.2
B19: 18 | C19: ﾗｲﾝﾎﾟﾝﾌﾟ | D19: cv3 | E19: 煙道・煙突取付工事 | K19: 049836000 | L19: ﾊｳｽｶｵﾝｷ | M19: HK6030TCV | N19: 台 | O19: 1814000 | P19: 722990 | Q19: 2.2 | T19: ---------- | AI19: 052496000 | AJ19: ｼﾝｸﾛﾋｰﾀ | AK19: SBM150HMT_5 12A 高温出湯 | AL19: 台 | AM19: 3875000 | AN19: 949050 | AO19: 3 | AQ19: 042007000 | AR19: ｵｰﾄｶﾝ | AS19: AWH-1001SA | AT19: 台 | AU19: 1295000 | AV19: 399360 | AW19: 1.9 | BP19: ｴﾛﾌｨﾝﾁｭｰﾌﾞ（STK 5KF） | BQ19: 32A 32F 1000L | BR19: 本 | BS19: =ROUND(BT19/0.4,-3) -> 65000 | BT19: 26000 | BU19: 0.13 | CV19: ﾗｲﾝﾎﾟﾝﾌﾟ | CW19: 50Hz φ50 3.7kW | CX19: 台 | CY19: 440000 | CZ19: =ROUND(CY19*0.53,-1) -> 233200 | DA19: 0.8 | DC19: 039749000 | DD19: EHPﾊｲﾌﾞﾘｯﾄﾞ制御基板ｾｯﾄ | DE19: EHP-HCS | DF19: 式 | DG19: 71900 | DH19: 4500 | DT19: 膨張ﾀﾝｸ | DU19: HUW-100 ボールタップ一般型 | DV19: 台 | DW19: 466000 | DX19: 256300 | DY19: 1.5 | EA19: 044668000 | EB19: 消火器設置台 | EC19: ＶＴ１ＲＢ | ED19: 個 | EE19: 4530 | EF19: 1250 | EG19: 0.1 | EI19: 105768000 | EJ19: 煙室ｾｯﾄ | EK19: ES-2327 | EL19: ｾｯﾄ | EM19: 119000 | EN19: 36590 | EO19: 0.5 | EQ19: RE0000183 | ER19: ﾊﾟﾜｰﾀﾞｸﾄ | ES19: 折幅550×200m(0.07) | ET19: 本 | EU19: 33500 | EV19: 17200 | EW19: 0 | EZ19: ｽﾊﾟｲﾗﾙﾀﾞｸﾄ(SUS) | FA19: φ500 | FB19: ｍ | FC19: 54900 | FD19: =FC19*0.65 -> 35685 | FE19: 0.2 | FO19: 051246000 | FP19: ﾊｳｽｶｵﾝｷ | FQ19: HK6030GESV | FR19: 台 | FS19: 2400000 | FT19: 811530 | FU19: 2.2 | GE19: 051052000 | GF19: ﾊｳｽｶｵﾝｷ（13Aｶﾞｽ焚き） | GG19: HK2030TCN | GH19: 台 | GI19: 1197000 | GJ19: 553550 | GK19: 1.25 | GM19: 039200000 | GN19: ｶﾜｲﾀｰ | GO19: KT2026TPF3 | GP19: 台 | GQ19: 4017000 | GR19: 1185670 | GS19: 3.1 | GV19: SGPｴﾛﾌｨﾝﾁｭｰﾌﾞ | GW19: 32A 32F 1000L | GX19: 本 | GY19: =ROUND(GZ19/0.33,-3) -> 80000 | GZ19: 26400 | HA19: 0.13
B20: 19 | C20: ﾊﾟｯｹｰｼﾞｴｱｺﾝ(NGP・重工) | D20: dd3 | E20: 煙道保温工事 | K20: 049837000 | L20: ﾊｳｽｶｵﾝｷ | M20: HK6030TEV | N20: 台 | O20: 1882000 | P20: 792990 | Q20: 2.2 | S20: 051160000 | T20: ｸﾞﾛｳｴｱ（灯油焚き） | U20: CG-254S1 | V20: 台 | W20: 322000 | X20: 159980 | Y20: 0.5 | AI20: 046051000 | AJ20: ｼﾝｸﾛﾋｰﾀ | AK20: SBM150HLT_4 LPG 高温出湯 | AL20: 台 | AM20: 3875000 | AN20: 938600 | AO20: 3 | AQ20: 042008000 | AR20: ｵｰﾄｶﾝ | AS20: AWH-1201SA | AT20: 台 | AU20: 1484000 | AV20: 473840 | AW20: 2.05 | BP20: ---------- | CV20: ---------- | DT20: 膨張ﾀﾝｸ | DU20: HUW-150 ボールタップ一般型 | DV20: 台 | DW20: 544000 | DX20: 299200 | DY20: 2 | EB20: ---------- | EI20: 105769000 | EJ20: 煙室ｾｯﾄ | EK20: ES-4027 | EL20: ｾｯﾄ | EM20: 126000 | EN20: 40820 | EO20: 0.5 | ER20: ---------- | EZ20: ｽﾊﾟｲﾗﾙﾀﾞｸﾄ(SUS) | FA20: φ550 | FB20: ｍ | FC20: 60100 | FD20: =FC20*0.65 -> 39065 | FE20: 0.2 | FO20: 051247000 | FP20: ﾊｳｽｶｵﾝｷ | FQ20: HK6030GFSV | FR20: 台 | FS20: 2268000 | FT20: 712620 | FU20: 2.2 | GE20: 051062000 | GF20: ﾊｳｽｶｵﾝｷ（13Aｶﾞｽ焚き） | GG20: HK2030TEN | GH20: 台 | GI20: 1215000 | GJ20: 562370 | GK20: 1.25 | GM20: 105852000 | GN20: ｶﾜｲﾀｰ | GO20: KT2026TPHF | GP20: 台 | GQ20: 3721000 | GR20: 1087100 | GS20: 3.1 | GV20: ----------
B21: 20 | C21: ﾁﾗｰﾕﾆｯﾄ(ﾀﾞｲｷﾝ) | D21: dl3 | E21: ---------- | K21: 049838000 | L21: ﾊｳｽｶｵﾝｷ | M21: HK6030TFV | N21: 台 | O21: 1763000 | P21: 685520 | Q21: 2.2 | S21: 051161000 | T21: ｸﾞﾛｳｴｱ（灯油焚き） | U21: CG-254S2 | V21: 台 | W21: 344000 | X21: 168500 | Y21: 0.5 | AI21: 052497000 | AJ21: ｼﾝｸﾛﾋｰﾀ | AK21: SBM150HLT_5 LPG 高温出湯 | AL21: 台 | AM21: 3875000 | AN21: 949050 | AO21: 3 | AQ21: 042009000 | AR21: ｵｰﾄｶﾝ | AS21: AWH-1501SA | AT21: 台 | AU21: 1729000 | AV21: 475170 | AW21: 2.15 | BP21: ｴﾛﾌｨﾝﾁｭｰﾌﾞ（STK 5KF） | BQ21: 40A 25F 5500L | BR21: 本 | BS21: =ROUND(BT21/0.4,-3) -> 89000 | BT21: 35400 | BU21: 0.72 | CV21: ﾗｲﾝﾎﾟﾝﾌﾟ | CW21: 50Hz φ65 0.75kW | CX21: 台 | CY21: 246000 | CZ21: =ROUND(CY21*0.53,-1) -> 130380 | DA21: 0.7 | DT21: 同上架台 | DU21: 溶融亜鉛メッキ（SS400) 500H 40用 | DV21: 組 | DW21: 60000 | DX21: 33000 | DY21: 0.3 | EB21: ｵｲﾙﾀﾝｸ | EC21: KS1-399SZ | ED21: 基 | EE21: 100300 | EF21: 40200 | EG21: 0.3 | EI21: 105770000 | EJ21: 煙室ｾｯﾄ | EK21: ES-5627 | EL21: ｾｯﾄ | EM21: 145000 | EN21: 52890 | EO21: 0.5 | EQ21: RE0000080 | ER21: ｸﾛｽﾗﾑﾀﾞｸﾄ | ES21: 折幅630×15m | ET21: 本 | EU21: 12200 | EV21: 5990 | EW21: 0 | EZ21: ｽﾊﾟｲﾗﾙﾀﾞｸﾄ(SUS) | FA21: φ600 | FB21: ｍ | FC21: 65400 | FD21: =FC21*0.65 -> 42510 | FE21: 0.24 | FP21: ---------- | GE21: 051054000 | GF21: ﾊｳｽｶｵﾝｷ（13Aｶﾞｽ焚き） | GG21: HK3030TCN | GH21: 台 | GI21: 1592000 | GJ21: 616300 | GK21: 1.45 | GM21: 039202000 | GN21: ｶﾜｲﾀｰ | GO21: KT2026TPG3 | GP21: 台 | GQ21: 4017000 | GR21: 1204760 | GS21: 3.1 | GV21: SGPｴﾛﾌｨﾝﾁｭｰﾌﾞ | GW21: 40A 25F 5500L | GX21: 本 | GY21: =ROUND(GZ21/0.33,-3) -> 116000 | GZ21: 38200 | HA21: 0.72
B22: 21 | C22: ｸｰﾘﾝｸﾞﾀﾜｰ | D22: cf3 | E22: ｴﾛﾌｨﾝ取付工事 | K22: 050747000 | L22: ﾊｳｽｶｵﾝｷ | M22: HK8030GCV | N22: 台 | O22: 2623000 | P22: 1068730 | Q22: 2.8 | S22: 051162000 | T22: ｸﾞﾛｳｴｱ（灯油焚き） | U22: CG-554T2 | V22: 台 | W22: 413000 | X22: 177140 | Y22: 0.7 | AI22: 052498000 | AJ22: ｼﾝｸﾛﾋｰﾀ | AK22: SBM150HNTJ_2 13A 高温,直結 | AL22: 台 | AM22: 4118000 | AN22: 1012010 | AO22: 3 | AR22: ---------- | BP22: ｴﾛﾌｨﾝﾁｭｰﾌﾞ（STK 5KF） | BQ22: 40A 25F 4000L | BR22: 本 | BS22: =ROUND(BT22/0.4,-3) -> 81000 | BT22: 32200 | BU22: 0.52 | CV22: ﾗｲﾝﾎﾟﾝﾌﾟ | CW22: 50Hz φ65 1.5kW | CX22: 台 | CY22: 289000 | CZ22: =ROUND(CY22*0.53,-1) -> 153170 | DA22: 0.8 | DT22: 同上架台 | DU22: 溶融亜鉛メッキ（SS400) 500H 60用 | DV22: 組 | DW22: 60000 | DX22: 33000 | DY22: 0.3 | EB22: ｵｲﾙﾀﾝｸ | EC22: KS2-490SJ | ED22: 基 | EE22: 98800 | EF22: 36300 | EG22: 0.3 | EI22: 039393000 | EJ22: 煙室ｾｯﾄ | EK22: ES-8026 | EL22: ｾｯﾄ | EM22: 147000 | EN22: 64190 | EO22: 0.7 | EQ22: RE0000081 | ER22: ｸﾛｽﾗﾑﾀﾞｸﾄ | ES22: 折幅630×20m | ET22: 本 | EU22: 15300 | EV22: 7930 | EW22: 0 | EZ22: ﾀﾞｸﾄﾍﾞﾝﾄﾞ(亜鉛) | FA22: φ200 | FB22: 個 | FC22: 4300 | FD22: =FC22*0.65 -> 2795 | FE22: 0.16 | FG22: 044722000 | FH22: ﾊﾟﾈﾙﾌﾚｯｼｬｰ | FI22: HFP-1503 | FJ22: 台 | FK22: 2911000 | FL22: 1060000 | FP22: ﾊｳｽｶｵﾝｷ | FQ22: HK8030GCSV | FR22: 台 | FS22: 2975000 | FT22: 1030240 | FU22: 2.8 | GE22: 051064000 | GF22: ﾊｳｽｶｵﾝｷ（13Aｶﾞｽ焚き） | GG22: HK3030TEN | GH22: 台 | GI22: 1606000 | GJ22: 615630 | GK22: 1.45 | GM22: 026284000 | GN22: ｶﾜｲﾀｰ | GO22: KT2026TPHG | GP22: 台 | GQ22: 3721000 | GR22: 1106190 | GS22: 3.1 | GV22: SGPｴﾛﾌｨﾝﾁｭｰﾌﾞ | GW22: 40A 25F 4000L | GX22: 本 | GY22: =ROUND(GZ22/0.33,-3) -> 103000 | GZ22: 34100 | HA22: 0.52
B23: 22 | C23: 蓄熱ﾀﾝｸ | D23: cn3 | E23: 支持金具取付工事 | K23: 050748000 | L23: ﾊｳｽｶｵﾝｷ | M23: HK8030GFV | N23: 台 | O23: 2572000 | P23: 1024260 | Q23: 2.8 | S23: 051163000 | T23: ｸﾞﾛｳｴｱ（灯油焚き） | U23: CG-854T2 | V23: 台 | W23: 537000 | X23: 240490 | Y23: 0.9 | AI23: 052499000 | AJ23: ｼﾝｸﾛﾋｰﾀ | AK23: SBM150HMTJ_2 12A 高温,直結 | AL23: 台 | AM23: 4118000 | AN23: 1011880 | AO23: 3 | AQ23: 042029000 | AR23: ｵｰﾄｶﾝ | AS23: AWH-501GBL | AT23: 台 | AU23: 1900000 | AV23: 520580 | AW23: 1.3 | BP23: ｴﾛﾌｨﾝﾁｭｰﾌﾞ（STK 5KF） | BQ23: 40A 25F 3500L | BR23: 本 | BS23: =ROUND(BT23/0.4,-3) -> 78000 | BT23: 31200 | BU23: 0.46 | CV23: ﾗｲﾝﾎﾟﾝﾌﾟ | CW23: 50Hz φ65 2.2kW | CX23: 台 | CY23: 362000 | CZ23: =ROUND(CY23*0.53,-1) -> 191860 | DA23: 0.8 | DT23: 同上架台 | DU23: 溶融亜鉛メッキ（SS400) 500H 80用 | DV23: 組 | DW23: 80000 | DX23: 44000 | DY23: 0.3 | EB23: ｵｲﾙﾀﾝｸ | EC23: YMA-990G1 | ED23: 基 | EE23: 394500 | EF23: 236700 | EG23: 1 | EJ23: ---------- | EQ23: RE0000082 | ER23: ｸﾛｽﾗﾑﾀﾞｸﾄ | ES23: 折幅630×30m | ET23: 本 | EU23: 21800 | EV23: 11770 | EW23: 0 | EZ23: ﾀﾞｸﾄﾍﾞﾝﾄﾞ(亜鉛) | FA23: φ225 | FB23: 個 | FC23: 5100 | FD23: =FC23*0.65 -> 3315 | FE23: 0.18 | FH23: --------------- | FP23: ﾊｳｽｶｵﾝｷ | FQ23: HK8030GFSV | FR23: 台 | FS23: 2969000 | FT23: 1014370 | FU23: 2.8 | GE23: 051072000 | GF23: ﾊｳｽｶｵﾝｷ（13Aｶﾞｽ焚き） | GG23: HK3030TFN | GH23: 台 | GI23: 1554000 | GJ23: 593350 | GK23: 1.45 | GV23: SGPｴﾛﾌｨﾝﾁｭｰﾌﾞ | GW23: 40A 25F 3500L | GX23: 本 | GY23: =ROUND(GZ23/0.33,-3) -> 99000 | GZ23: 32800 | HA23: 0.46
B24: 23 | C24: 膨張ﾀﾝｸ(ﾎｰｺｽ) | D24: dt3 | E24: 防油堤及びﾀﾝｸ基礎工事 | K24: 050745000 | L24: ﾊｳｽｶｵﾝｷ | M24: HK8030FCV | N24: 台 | O24: 2623000 | P24: 1153380 | Q24: 2.8 | T24: ---------- | AI24: 052500000 | AJ24: ｼﾝｸﾛﾋｰﾀ | AK24: SBM150HLTJ_2 LPG 高温,直結 | AL24: 台 | AM24: 4118000 | AN24: 1011880 | AO24: 3 | AQ24: 042031000 | AR24: ｵｰﾄｶﾝ | AS24: AWH-601GBL | AT24: 台 | AU24: 1974000 | AV24: 564960 | AW24: 1.4 | BP24: ｴﾛﾌｨﾝﾁｭｰﾌﾞ（STK 5KF） | BQ24: 40A 25F 3000L | BR24: 本 | BS24: =ROUND(BT24/0.4,-3) -> 75000 | BT24: 30000 | BU24: 0.4 | CV24: ﾗｲﾝﾎﾟﾝﾌﾟ | CW24: 50Hz φ65 3.7kW | CX24: 台 | CY24: 440000 | CZ24: =ROUND(CY24*0.53,-1) -> 233200 | DA24: 0.8 | DT24: 同上架台 | DU24: 溶融亜鉛メッキ（SS400) 500H 100用 | DV24: 組 | DW24: 80000 | DX24: 44000 | DY24: 0.3 | EB24: 防油堤 | EC24: AL-500G | ED24: 基 | EE24: 128400 | EF24: 77040 | EG24: 2.3 | EI24: 308793000 | EJ24: 煙突直管 | EK24: φ120 | EL24: 本 | EM24: 8470 | EN24: 2090 | EO24: 0.1 | EQ24: RE0000083 | ER24: ｸﾛｽﾗﾑﾀﾞｸﾄ | ES24: 折幅630×40m | ET24: 本 | EU24: 29200 | EV24: 15760 | EW24: 0 | EZ24: ﾀﾞｸﾄﾍﾞﾝﾄﾞ(亜鉛) | FA24: φ250 | FB24: 個 | FC24: 6400 | FD24: =FC24*0.65 -> 4160 | FE24: 0.18 | GE24: 051056000 | GF24: ﾊｳｽｶｵﾝｷ（13Aｶﾞｽ焚き） | GG24: HK4030TCN | GH24: 台 | GI24: 1919000 | GJ24: 735170 | GK24: 1.7 | GV24: SGPｴﾛﾌｨﾝﾁｭｰﾌﾞ | GW24: 40A 25F 3000L | GX24: 本 | GY24: =ROUND(GZ24/0.33,-3) -> 95000 | GZ24: 31400 | HA24: 0.4
B25: 24 | C25: ｵｲﾙﾀﾝｸ・消防関連 | D25: eb3 | E25: 矩体の孔明け補修工事 | K25: 050746000 | L25: ﾊｳｽｶｵﾝｷ | M25: HK8030FFV | N25: 台 | O25: 2572000 | P25: 1089470 | Q25: 2.8 | S25: 031617000 | T25: ｸﾞﾛｳｴｱ（LPガス焚き） | U25: CG-205SL | V25: 台 | W25: 247000 | X25: 117150 | AJ25: ----------- | AQ25: 042033000 | AR25: ｵｰﾄｶﾝ | AS25: AWH-701GBL | AT25: 台 | AU25: 2066000 | AV25: 564960 | AW25: 1.55 | BP25: ｴﾛﾌｨﾝﾁｭｰﾌﾞ（STK 5KF） | BQ25: 40A 25F 2750L | BR25: 本 | BS25: =ROUND(BT25/0.4,-3) -> 74000 | BT25: 29500 | BU25: 0.36 | CV25: ﾗｲﾝﾎﾟﾝﾌﾟ | CW25: 50Hz φ65 5.5kW | CX25: 台 | CY25: 585000 | CZ25: =ROUND(CY25*0.53,-1) -> 310050 | DA25: 1.2 | DT25: 同上架台 | DU25: 溶融亜鉛メッキ（SS400) 500H 150用 | DV25: 組 | DW25: 83000 | DX25: 45700 | DY25: 0.3 | EB25: 防油堤 | EC25: BYT-490K | ED25: 基 | EE25: 233300 | EF25: 116650 | EG25: 2.3 | EI25: 181571000 | EJ25: 煙突直管 | EK25: φ150 | EL25: 本 | EM25: 9930 | EN25: 2290 | EO25: 0.1 | EQ25: RE0000084 | ER25: ｸﾛｽﾗﾑﾀﾞｸﾄ | ES25: 折幅630×50m | ET25: 本 | EU25: 35400 | EV25: 19430 | EW25: 0 | EZ25: ﾀﾞｸﾄﾍﾞﾝﾄﾞ(亜鉛) | FA25: φ300 | FB25: 個 | FC25: 9000 | FD25: =FC25*0.65 -> 5850 | FE25: 0.18 | GE25: 051066000 | GF25: ﾊｳｽｶｵﾝｷ（13Aｶﾞｽ焚き） | GG25: HK4030TEN | GH25: 台 | GI25: 1969000 | GJ25: 763820 | GK25: 1.7 | GV25: SGPｴﾛﾌｨﾝﾁｭｰﾌﾞ | GW25: 40A 25F 2750L | GX25: 本 | GY25: =ROUND(GZ25/0.33,-3) -> 94000 | GZ25: 30900 | HA25: 0.36
B26: 25 | C26: ｽﾊﾟｲﾗﾙﾀﾞｸﾄ | D26: ez3 | E26: 孔明け補修工事 | L26: ---------- | S26: 041665000 | T26: CG-205用架台セット | U26: BCK-1100 | V26: ｾｯﾄ | W26: 48600 | X26: 19220 | AI26: 043555000 | AJ26: ｼﾝｸﾛﾋｰﾀ | AK26: SBM150UNT_2 | AL26: 台 | AM26: 5177000 | AN26: 1401900 | AO26: 3 | AQ26: 042035000 | AR26: ｵｰﾄｶﾝ | AS26: AWH-801GBL | AT26: 台 | AU26: 2188000 | AV26: 633350 | AW26: 1.65 | BP26: ｴﾛﾌｨﾝﾁｭｰﾌﾞ（STK 5KF） | BQ26: 40A 25F 2000L | BR26: 本 | BS26: =ROUND(BT26/0.4,-3) -> 70000 | BT26: 27900 | BU26: 0.26 | CV26: ---------- | DT26: ---------- | EB26: 防油堤 | EC26: NS1.9A(ﾌﾟﾚｷｬｽﾄ) | ED26: 基 | EE26: 280000 | EF26: 68750 | EG26: 5 | EI26: 131575000 | EJ26: 煙突直管 | EK26: φ175 | EL26: 本 | EM26: 11300 | EN26: 1880 | EO26: 0.1 | EQ26: RE0000085 | ER26: ｸﾛｽﾗﾑﾀﾞｸﾄ | ES26: 折幅630×100m | ET26: 本 | EU26: 69400 | EV26: 38790 | EW26: 0 | EZ26: ﾀﾞｸﾄﾍﾞﾝﾄﾞ(亜鉛) | FA26: φ350 | FB26: 個 | FC26: 11300 | FD26: =FC26*0.65 -> 7345 | FE26: 0.19 | GE26: 051074000 | GF26: ﾊｳｽｶｵﾝｷ（13Aｶﾞｽ焚き） | GG26: HK4030TFN | GH26: 台 | GI26: 1877000 | GJ26: 693090 | GK26: 1.7 | GV26: SGPｴﾛﾌｨﾝﾁｭｰﾌﾞ | GW26: 40A 25F 2000L | GX26: 本 | GY26: =ROUND(GZ26/0.33,-3) -> 87000 | GZ26: 28800 | HA26: 0.26
B27: 26 | C27: ｱﾙﾐﾌﾚｷﾀﾞｸﾄ | D27: fh3 | E27: ﾀﾞｸﾄ敷設工事 | K27: 052771000 | L27: ﾊｳｽｶｵﾝｷ | M27: HK2029TCV | N27: 台 | O27: 797000 | P27: 383340 | Q27: 1.25 | S27: 051167000 | T27: ｸﾞﾛｳｴｱ（LPガス焚き） | U27: CG-254S1G | V27: 台 | W27: 501000 | X27: 279060 | Y27: 0.5 | AI27: 043557000 | AJ27: ｼﾝｸﾛﾋｰﾀ | AK27: SBM150ULT_2 | AL27: 台 | AM27: 5177000 | AN27: 1399060 | AO27: 3 | AQ27: 042037000 | AR27: ｵｰﾄｶﾝ | AS27: AWH-901GBL | AT27: 台 | AU27: 2264000 | AV27: 639410 | AW27: 1.75 | BP27: ｴﾛﾌｨﾝﾁｭｰﾌﾞ（STK 5KF） | BQ27: 40A 25F 1500L | BR27: 本 | BS27: =ROUND(BT27/0.4,-3) -> 68000 | BT27: 27200 | BU27: 0.2 | CV27: ﾗｲﾝﾎﾟﾝﾌﾟ | CW27: 50Hz φ80 1.5kW | CX27: 台 | CY27: 302000 | CZ27: =ROUND(CY27*0.53,-1) -> 160060 | DA27: 0.9 | DT27: 密閉膨張ﾀﾝｸ | DU27: ER-8 5.3L | DV27: 基 | DW27: 22000 | DX27: 12100 | DY27: 0.3 | EI27: 308714000 | EJ27: 煙突直管 | EK27: φ225 | EL27: 本 | EM27: 12600 | EN27: 3340 | EO27: 0.1 | EQ27: RE0000086 | ER27: ｸﾛｽﾗﾑﾀﾞｸﾄ | ES27: 折幅900×15m | ET27: 本 | EU27: 15300 | EV27: 8240 | EW27: 0 | EZ27: ﾀﾞｸﾄﾍﾞﾝﾄﾞ(亜鉛) | FA27: φ400 | FB27: 個 | FC27: 15500 | FD27: =FC27*0.65 -> 10075 | FE27: 0.19 | GE27: 051058000 | GF27: ﾊｳｽｶｵﾝｷ（13Aｶﾞｽ焚き） | GG27: HK5030TCN | GH27: 台 | GI27: 2098000 | GJ27: 824320 | GK27: 2 | GV27: SGPｴﾛﾌｨﾝﾁｭｰﾌﾞ | GW27: 40A 25F 1500L | GX27: 本 | GY27: =ROUND(GZ27/0.33,-3) -> 84000 | GZ27: 27600 | HA27: 0.2
B28: 27 | C28: ﾌﾚｯｼｬｰｼﾘｰｽﾞ | D28: fh22 | E28: 消耗品雑材 | K28: 052772000 | L28: ﾊｳｽｶｵﾝｷ | M28: HK2029TEV | N28: 台 | O28: 821000 | P28: 393450 | Q28: 1.25 | S28: 051168000 | T28: ｸﾞﾛｳｴｱ（LPガス焚き） | U28: CG-254S2G | V28: 台 | W28: 518000 | X28: 288220 | Y28: 0.5 | AJ28: ----------- | AQ28: 042039000 | AR28: ｵｰﾄｶﾝ | AS28: AWH-1001GBL | AT28: 台 | AU28: 2431000 | AV28: 638120 | AW28: 1.9 | BP28: ｴﾛﾌｨﾝﾁｭｰﾌﾞ（STK 5KF） | BQ28: 40A 25F 1000L | BR28: 本 | BS28: =ROUND(BT28/0.4,-3) -> 65000 | BT28: 25800 | BU28: 0.13 | CV28: ﾗｲﾝﾎﾟﾝﾌﾟ | CW28: 50Hz φ80 2.2kW | CX28: 台 | CY28: 351000 | CZ28: =ROUND(CY28*0.53,-1) -> 186030 | DA28: 1 | DT28: 密閉膨張ﾀﾝｸ | DU28: ER-18 11.4L | DV28: 基 | DW28: 37000 | DX28: 20350 | DY28: 0.5 | EI28: 131555000 | EJ28: 煙突直管 | EK28: φ250 | EL28: 本 | EM28: 16400 | EN28: 3440 | EO28: 0.15 | EQ28: RE0000087 | ER28: ｸﾛｽﾗﾑﾀﾞｸﾄ | ES28: 折幅900×20m | ET28: 本 | EU28: 20300 | EV28: 10890 | EW28: 0 | EZ28: ﾀﾞｸﾄﾍﾞﾝﾄﾞ(亜鉛) | FA28: φ450 | FB28: 個 | FC28: 18900 | FD28: =FC28*0.65 -> 12285 | FE28: 0.2 | GE28: 051068000 | GF28: ﾊｳｽｶｵﾝｷ（13Aｶﾞｽ焚き） | GG28: HK5030TEN | GH28: 台 | GI28: 2168000 | GJ28: 902150 | GK28: 2 | GV28: SGPｴﾛﾌｨﾝﾁｭｰﾌﾞ | GW28: 40A 25F 1000L | GX28: 本 | GY28: =ROUND(GZ28/0.33,-3) -> 79000 | GZ28: 26200 | HA28: 0.13
K29: 052773000 | L29: ﾊｳｽｶｵﾝｷ | M29: HK3029TCV | N29: 台 | O29: 982000 | P29: 403820 | Q29: 1.45 | S29: 051169000 | T29: ｸﾞﾛｳｴｱ（LPガス焚き） | U29: CG-554TG2 | V29: 台 | W29: 684000 | X29: 291190 | Y29: 0.7 | AJ29: ｼﾝｸﾛﾋｰﾀ（A重油焚き） | AK29: SBB-1002HA | AL29: 台 | AM29: 9500000 | AN29: 3500000 | AO29: 7 | AQ29: 042041000 | AR29: ｵｰﾄｶﾝ | AS29: AWH-1201GBL | AT29: 台 | AU29: 2800000 | AV29: 757460 | AW29: 2.05 | BP29: ---------- | CV29: ﾗｲﾝﾎﾟﾝﾌﾟ | CW29: 50Hz φ80 3.7kW | CX29: 台 | CY29: 466000 | CZ29: =ROUND(CY29*0.53,-1) -> 246980 | DA29: 1 | DT29: 密閉膨張ﾀﾝｸ | DU29: ER-24 16.3L | DV29: 基 | DW29: 51000 | DX29: 28050 | DY29: 0.75 | EJ29: 煙突直管 | EK29: φ300 | EL29: 本 | EM29: 42600 | EN29: 19170 | EO29: 0.2 | EQ29: RE0000088 | ER29: ｸﾛｽﾗﾑﾀﾞｸﾄ | ES29: 折幅900×30m | ET29: 本 | EU29: 29000 | EV29: 16210 | EW29: 0 | EZ29: ﾀﾞｸﾄﾍﾞﾝﾄﾞ(亜鉛) | FA29: φ500 | FB29: 個 | FC29: 22900 | FD29: =FC29*0.65 -> 14885 | FE29: 0.2 | GE29: 051076000 | GF29: ﾊｳｽｶｵﾝｷ（13Aｶﾞｽ焚き） | GG29: HK5030TFN | GH29: 台 | GI29: 2048000 | GJ29: 791160 | GK29: 2 | GV29: ----------
K30: 052774000 | L30: ﾊｳｽｶｵﾝｷ | M30: HK3029TEV | N30: 台 | O30: 990000 | P30: 420930 | Q30: 1.45 | AJ30: 旧型 ｼﾝｸﾛﾋｰﾀ(LPG焚・中圧仕様) | AK30: SBB-1002HL | AL30: 台 | AM30: 9500000 | AN30: 3500000 | AO30: 7 | AQ30: 042043000 | AR30: ｵｰﾄｶﾝ | AS30: AWH-1501GBL | AT30: 台 | AU30: 3042000 | AV30: 752560 | AW30: 2.3 | BP30: ｴﾛﾌｨﾝﾁｭｰﾌﾞ（STK 5KF） | BQ30: 40A 32F 5500L | BR30: 本 | BS30: =ROUND(BT30/0.4,-3) -> 96000 | BT30: 38200 | BU30: 0.72 | CV30: ﾗｲﾝﾎﾟﾝﾌﾟ | CW30: 50Hz φ80 5.5kW | CX30: 台 | CY30: 592000 | CZ30: =ROUND(CY30*0.53,-1) -> 313760 | DA30: 1.2 | DT30: 密閉膨張ﾀﾝｸ | DU30: ER-35 23.8L | DV30: 基 | DW30: 69000 | DX30: 37950 | DY30: 1 | EJ30: 煙突直管 | EK30: φ350 | EL30: 本 | EM30: 51800 | EN30: 23310 | EO30: 0.2 | EQ30: RE0000089 | ER30: ｸﾛｽﾗﾑﾀﾞｸﾄ | ES30: 折幅900×40m | ET30: 本 | EU30: 39200 | EV30: 21700 | EW30: 0 | EZ30: ﾀﾞｸﾄﾍﾞﾝﾄﾞ(亜鉛) | FA30: φ550 | FB30: 個 | FC30: 27300 | FD30: =FC30*0.65 -> 17745 | FE30: 0.2 | GE30: 051060000 | GF30: ﾊｳｽｶｵﾝｷ（13Aｶﾞｽ焚き） | GG30: HK6030TCN | GH30: 台 | GI30: 2307000 | GJ30: 882310 | GK30: 2.2 | GV30: SGPｴﾛﾌｨﾝﾁｭｰﾌﾞ | GW30: 40A 32F 5500L | GX30: 本 | GY30: =ROUND(GZ30/0.33,-3) -> 124000 | GZ30: 41000 | HA30: 0.72
K31: 052775000 | L31: ﾊｳｽｶｵﾝｷ | M31: HK4029TCV | N31: 台 | O31: 1221000 | P31: 482640 | Q31: 1.7 | AJ31: ｼﾝｸﾛﾋｰﾀ(13A焚・中圧仕様) | AK31: SBB-1002HN | AL31: 台 | AM31: 9500000 | AN31: 3500000 | AO31: 7 | AQ31: 042045000 | AR31: ｵｰﾄｶﾝ | AS31: AWH-1801GBL | AT31: 台 | AU31: 3348000 | AV31: 760300 | AW31: 2.6 | BP31: ｴﾛﾌｨﾝﾁｭｰﾌﾞ（STK 5KF） | BQ31: 40A 32F 4000L | BR31: 本 | BS31: =ROUND(BT31/0.4,-3) -> 84000 | BT31: 33600 | BU31: 0.52 | CV31: ﾗｲﾝﾎﾟﾝﾌﾟ | CW31: 50Hz φ80 7.5kW | CX31: 台 | CY31: 674000 | CZ31: =ROUND(CY31*0.53,-1) -> 357220 | DA31: 1.5 | DT31: 密閉膨張ﾀﾝｸ | DU31: ER-50 30.0L | DV31: 基 | DW31: 84000 | DX31: 46200 | DY31: 1.25 | EI31: 308796000 | EJ31: 煙突半直管 | EK31: φ120 | EL31: 本 | EM31: 5170 | EN31: 1040 | EO31: 0.1 | EQ31: RE0000090 | ER31: ｸﾛｽﾗﾑﾀﾞｸﾄ | ES31: 折幅900×50m | ET31: 本 | EU31: 49300 | EV31: 26850 | EW31: 0 | EZ31: ﾀﾞｸﾄﾍﾞﾝﾄﾞ(亜鉛) | FA31: φ600 | FB31: 個 | FC31: 31700 | FD31: =FC31*0.65 -> 20605 | FE31: 0.24 | GE31: 051070000 | GF31: ﾊｳｽｶｵﾝｷ（13Aｶﾞｽ焚き） | GG31: HK6030TEN | GH31: 台 | GI31: 2381000 | GJ31: 974610 | GK31: 2.2 | GV31: SGPｴﾛﾌｨﾝﾁｭｰﾌﾞ | GW31: 40A 32F 4000L | GX31: 本 | GY31: =ROUND(GZ31/0.33,-3) -> 110000 | GZ31: 36200 | HA31: 0.52
K32: 052776000 | L32: ﾊｳｽｶｵﾝｷ | M32: HK4029TEV | N32: 台 | O32: 1283000 | P32: 508050 | Q32: 1.7 | AJ32: ｼﾝｸﾛﾋｰﾀ（LPG焚・超高効率仕様） | AK32: SBB-1005HL | AL32: 台 | AM32: 11500000 | AN32: 5400000 | AO32: 9 | AQ32: 042047000 | AR32: ｵｰﾄｶﾝ | AS32: AWH-2001GBL | AT32: 台 | AU32: 3499000 | AV32: 756820 | AW32: 2.75 | BP32: ｴﾛﾌｨﾝﾁｭｰﾌﾞ（STK 5KF） | BQ32: 40A 32F 3500L | BR32: 本 | BS32: =ROUND(BT32/0.4,-3) -> 82000 | BT32: 32800 | BU32: 0.46 | CV32: ﾗｲﾝﾎﾟﾝﾌﾟ | CW32: 50Hz φ80 11kW | CX32: 台 | CY32: 910000 | CZ32: =ROUND(CY32*0.53,-1) -> 482300 | DA32: 2 | DT32: ---------- | EI32: 308802000 | EJ32: 煙突半直管 | EK32: φ150 | EL32: 本 | EM32: 5960 | EN32: 1250 | EO32: 0.1 | EQ32: RE0000091 | ER32: ｸﾛｽﾗﾑﾀﾞｸﾄ | ES32: 折幅900×100m | ET32: 本 | EU32: 96000 | EV32: 53630 | EW32: 0 | EZ32: ﾀﾞｸﾄﾍﾞﾝﾄﾞ(SUS) | FA32: φ200 | FB32: 個 | FC32: 21300 | FD32: =FC32*0.65 -> 13845 | FE32: 0.16 | GE32: 051078000 | GF32: ﾊｳｽｶｵﾝｷ（13Aｶﾞｽ焚き） | GG32: HK6030TFN | GH32: 台 | GI32: 2131000 | GJ32: 843390 | GK32: 2.2 | GV32: SGPｴﾛﾌｨﾝﾁｭｰﾌﾞ | GW32: 40A 32F 3500L | GX32: 本 | GY32: =ROUND(GZ32/0.33,-3) -> 105000 | GZ32: 34600 | HA32: 0.46
K33: 052777000 | L33: ﾊｳｽｶｵﾝｷ | M33: HK5029TCV | N33: 台 | O33: 1430000 | P33: 589070 | Q33: 2 | AJ33: ----------- | AR33: ---------- | BP33: ｴﾛﾌｨﾝﾁｭｰﾌﾞ（STK 5KF） | BQ33: 40A 32F 3000L | BR33: 本 | BS33: =ROUND(BT33/0.4,-3) -> 79000 | BT33: 31500 | BU33: 0.4 | CV33: ---------- | DT33: 密閉膨張ﾀﾝｸ | DU33: JTX-80 50L | DV33: 基 | DW33: 107000 | DX33: 58850 | DY33: 2.25 | EI33: 313348000 | EJ33: 煙突半直管 | EK33: φ225 | EL33: 本 | EM33: 11000 | EN33: 1880 | EO33: 0.1 | EQ33: RE0000098 | ER33: ｸﾛｽﾗﾑﾀﾞｸﾄ | ES33: 折幅1100×15m | ET33: 本 | EU33: 17800 | EV33: 8950 | EW33: 0 | EZ33: ﾀﾞｸﾄﾍﾞﾝﾄﾞ(SUS) | FA33: φ225 | FB33: 個 | FC33: 25800 | FD33: =FC33*0.65 -> 16770 | FE33: 0.18 | GV33: SGPｴﾛﾌｨﾝﾁｭｰﾌﾞ | GW33: 40A 32F 3000L | GX33: 本 | GY33: =ROUND(GZ33/0.33,-3) -> 100000 | GZ33: 33000 | HA33: 0.4
C34: 【変更履歴】 | K34: 052778000 | L34: ﾊｳｽｶｵﾝｷ | M34: HK5029TEV | N34: 台 | O34: 1500000 | P34: 641450 | Q34: 2 | AJ34: ｼﾝｸﾛﾋｰﾀ(高温水仕様) | AK34: SB-306MＨ□Ｈ(油焚) | AL34: 台 | AM34: 5156000 | AN34: 1178400 | AQ34: 042028000 | AR34: ｵｰﾄｶﾝ | AS34: AWH-501GBN | AT34: 台 | AU34: 1900000 | AV34: 507680 | AW34: 1.3 | BP34: ｴﾛﾌｨﾝﾁｭｰﾌﾞ（STK 5KF） | BQ34: 40A 32F 2750L | BR34: 本 | BS34: =ROUND(BT34/0.4,-3) -> 77000 | BT34: 30900 | BU34: 0.36 | CV34: ﾗｲﾝﾎﾟﾝﾌﾟ | CW34: 60Hz φ25 0.15kW | CX34: 台 | CY34: 102000 | CZ34: =ROUND(CY34*0.53,-1) -> 54060 | DA34: 0.3 | DT34: 密閉膨張ﾀﾝｸ | DU34: JTX-100 63L | DV34: 基 | DW34: 153000 | DX34: 84150 | DY34: 2.5 | EI34: 322370000 | EJ34: 煙突半直管 | EK34: φ250 | EL34: 本 | EM34: 23700 | EN34: 4490 | EO34: 0.1 | EQ34: RE0000099 | ER34: ｸﾛｽﾗﾑﾀﾞｸﾄ | ES34: 折幅1100×20m | ET34: 本 | EU34: 25500 | EV34: 11810 | EW34: 0 | EZ34: ﾀﾞｸﾄﾍﾞﾝﾄﾞ(SUS) | FA34: φ250 | FB34: 個 | FC34: 30500 | FD34: =FC34*0.65 -> 19825 | FE34: 0.18 | GV34: SGPｴﾛﾌｨﾝﾁｭｰﾌﾞ | GW34: 40A 32F 2750L | GX34: 本 | GY34: =ROUND(GZ34/0.33,-3) -> 98000 | GZ34: 32300 | HA34: 0.36
C35: ’10.12訂正箇所 製品値上分 | K35: 052779000 | L35: ﾊｳｽｶｵﾝｷ | M35: HK5029TFV | N35: 台 | O35: 1360000 | P35: 557180 | Q35: 2 | AJ35: ｼﾝｸﾛﾋｰﾀ(高温水仕様) | AK35: SB-406MＨ□Ｈ(油焚) | AL35: 台 | AM35: 6783000 | AN35: 1550400 | AQ35: 042030000 | AR35: ｵｰﾄｶﾝ | AS35: AWH-601GBN | AT35: 台 | AU35: 1974000 | AV35: 561350 | AW35: 1.4 | BP35: ｴﾛﾌｨﾝﾁｭｰﾌﾞ（STK 5KF） | BQ35: 40A 32F 2000L | BR35: 本 | BS35: =ROUND(BT35/0.4,-3) -> 73000 | BT35: 29200 | BU35: 0.26 | CV35: ---------- | DT35: 密閉膨張ﾀﾝｸ | DU35: JTX-150 95L | DV35: 基 | DW35: 203000 | DX35: 111650 | DY35: 3 | EH35: =EF23/EE23 -> 0.6 | EJ35: ---------- | EQ35: RE0000100 | ER35: ｸﾛｽﾗﾑﾀﾞｸﾄ | ES35: 折幅1100×30m | ET35: 本 | EU35: 31500 | EV35: 17600 | EW35: 0 | EZ35: ﾀﾞｸﾄﾍﾞﾝﾄﾞ(SUS) | FA35: φ300 | FB35: 個 | FC35: 49100 | FD35: =FC35*0.65 -> 31915 | FE35: 0.18 | GV35: SGPｴﾛﾌｨﾝﾁｭｰﾌﾞ | GW35: 40A 32F 2000L | GX35: 本 | GY35: =ROUND(GZ35/0.33,-3) -> 91000 | GZ35: 29900 | HA35: 0.26
C36: ’10.11訂正箇所 部品値上分 | K36: 052780000 | L36: ﾊｳｽｶｵﾝｷ | M36: HK6029TCV | N36: 台 | O36: 1590000 | P36: 612410 | Q36: 2.2 | AJ36: ｼﾝｸﾛﾋｰﾀ(高温水仕様) | AK36: SB-506MＨ□Ｈ(油焚) | AL36: 台 | AM36: 7256000 | AN36: 1658400 | AQ36: 042032000 | AR36: ｵｰﾄｶﾝ | AS36: AWH-701GBN | AT36: 台 | AU36: 2066000 | AV36: 597350 | AW36: 1.55 | BP36: ｴﾛﾌｨﾝﾁｭｰﾌﾞ（STK 5KF） | BQ36: 40A 32F 1500L | BR36: 本 | BS36: =ROUND(BT36/0.4,-3) -> 69000 | BT36: 27600 | BU36: 0.2 | CV36: ﾗｲﾝﾎﾟﾝﾌﾟ | CW36: 60Hz φ32 0.25kW | CX36: 台 | CY36: 139000 | CZ36: =ROUND(CY36*0.53,-1) -> 73670 | DA36: 0.3 | DT36: 密閉膨張ﾀﾝｸ | DU36: JTX-200 120L | DV36: 基 | DW36: 273000 | DX36: 150150 | DY36: 3 | EH36: =EF24/EE24 -> 0.6 | EI36: 308799000 | EJ36: 煙突ｴﾋﾞﾏｶﾞﾘ | EK36: φ120 | EL36: 個 | EM36: 6490 | EN36: 1360 | EO36: 0.1 | EQ36: RE0000101 | ER36: ｸﾛｽﾗﾑﾀﾞｸﾄ | ES36: 折幅1100×40m | ET36: 本 | EU36: 43000 | EV36: 23550 | EW36: 0 | EZ36: ﾀﾞｸﾄﾍﾞﾝﾄﾞ(SUS) | FA36: φ350 | FB36: 個 | FC36: 59100 | FD36: =FC36*0.65 -> 38415 | FE36: 0.19 | GV36: SGPｴﾛﾌｨﾝﾁｭｰﾌﾞ | GW36: 40A 32F 1500L | GX36: 本 | GY36: =ROUND(GZ36/0.33,-3) -> 86000 | GZ36: 28300 | HA36: 0.2
